Workbook

Sheet Website_README
A1: Interactive website package - data and methodology
A3: Package purpose | B3: Back-up data for the GitHub Pages website. The interactive chart links each overlap bubble to the exact overlap units and relevant programs.
A4: Matched portfolio snapshot | B4: AstraZeneca 10 Feb 2026 and BMS 5 Feb 2026 pipeline disclosures.
A5: Late-stage program definition | B5: Unique lead investigational asset in Phase II or Phase III/pivotal/registration development; approved-indication expansions and major lifecycle-management programs excluded from the core count.
A6: Overlap count definition | B6: Number of distinct shared indication territories, modality classes, target/mechanism themes, or development-stage bands - not all possible AZ-BMS asset-pair permutations.
A7: Launch window | B7: Illustrative analyst scenario calculated from trial primary-completion year plus a stage-specific lag. It is not company guidance, a probability-adjusted forecast, or a regulatory prediction.
A8: Historical sales | B8: Investigational assets have no historical sales. The Commercial_Benchmarks sheet provides company-reported brand revenue for scale context; figures are generally not indication-specific.
A9: Website deployment | B9: Upload the package contents to a GitHub repository and enable GitHub Pages from the main branch / root folder. No build step is required.

Sheet README
A1: AstraZeneca + BMS: Portfolio Fit—or Collision?
A3: Purpose
A4: Backup workbook for a LinkedIn post examining where AstraZeneca and Bristol Myers Squibb have overlapping versus complementary late-stage R&D portfolios.
A7: Headline findings
A8: 1. The shared areas contain 41 of 62 mapped programs (66%), concentrated in solid-tumor oncology, hematology, immunology/respiratory/fibrosis and cardiovascular disease.
A9: 2. Oncology is the clearest collision zone: 18 solid-tumor programs plus 8 hematology programs across the two companies.
A10: 3. Complementarity is strongest outside oncology: AstraZeneca adds rare disease, renal/metabolic and infectious-disease breadth; BMS adds a distinct neuroscience foothold.
A11: 4. Counts show portfolio breadth—not program quality, probability of success, revenue potential, target-level duplication or antitrust risk.
A14: Methodology
A15: Snapshot dates | B15: AstraZeneca: 10 Feb 2026; BMS: 5 Feb 2026. Matching annual-report snapshots were used to improve comparability.
A16: Included | B16: Lead investigational assets or disclosed lead programs in Phase II or Phase III/pivotal/registration.
A17: Excluded | B17: Approved indications, additional indications for marketed products, and AstraZeneca significant life-cycle-management tables.
A18: Deduplication | B18: The same lead asset is counted once at its highest disclosed phase; multiple indications and combinations are consolidated under the lead investigational asset.
A19: Normalization | B19: Company therapy areas were harmonized into eight cross-company categories. AstraZeneca oncology assets were classified as solid-tumor oncology or hematology based on disclosed areas under investigation.
A20: Interpretation | B20: A “shared” category means both companies have late-stage activity in the broad therapeutic area; it does not prove direct mechanism, indication or asset duplication.
A23: Important current-event caveat
A24: Reuters reported on Aug. 5, 2026 that a senior source said there were no ongoing discussions between the companies. The analysis is therefore framed as a portfolio thought experiment, not an announced transaction.
A27: Stacked-footprint + count-based lollipop update
A28: The chart restores the stacked late-stage program bars above each disease area. AstraZeneca and BMS use logo-inspired company colors; bubble size and number show distinct overlap count, while red tone shows analyst-coded directness. Portfolio balance remains excluded.
A29: Reproduction: the Plot_Data tab feeds the R and Python scripts; the Visual_Settings tab records the exact palette and visual encodings.

Sheet Asset_Data
A1: Company | B1: Source therapeutic area | C1: Normalized area | D1: Lead investigational asset / program | E1: Highest disclosed phase in snapshot | F1: Modality / mechanism | G1: Representative area(s) under investigation | H1: Source snapshot date | I1: Source URL | J1: Methodology notes
A2: AstraZeneca | B2: Oncology | C2: Solid-tumor oncology | D2: AZD9574 | E2: Phase II | F2: PARP1 inhibitor | G2: Advanced solid malignancies | H2: 2026-02-10 | I2: https://www.astrazeneca.com/content/dam/az/Investor_Relations/annual-report-2025/pdf/AstraZeneca_Development_Pipeline_2025.pdf
A3: AstraZeneca | B3: Oncology | C3: Solid-tumor oncology | D3: camizestrant | E3: Phase III / registration | F3: Next-generation oral SERD | G3: HR+/HER2- breast cancer, including advanced and adjuvant settings | H3: 2026-02-10 | I3: https://www.astrazeneca.com/content/dam/az/Investor_Relations/annual-report-2025/pdf/AstraZeneca_Development_Pipeline_2025.pdf | J3: Combination trials counted once under the lead investigational asset.
A4: AstraZeneca | B4: Oncology | C4: Solid-tumor oncology | D4: FPI-2265 | E4: Phase II | F4: PSMA-targeted actinium radioconjugate | G4: Prostate cancer | H4: 2026-02-10 | I4: https://www.astrazeneca.com/content/dam/az/Investor_Relations/annual-report-2025/pdf/AstraZeneca_Development_Pipeline_2025.pdf
A5: AstraZeneca | B5: Oncology | C5: Solid-tumor oncology | D5: IPH5201 | E5: Phase II | F5: CD39 monoclonal antibody | G5: Neoadjuvant/adjuvant NSCLC; listed in combination with Imfinzi | H5: 2026-02-10 | I5: https://www.astrazeneca.com/content/dam/az/Investor_Relations/annual-report-2025/pdf/AstraZeneca_Development_Pipeline_2025.pdf | J5: Marketed combination backbone excluded from the asset count.
A6: AstraZeneca | B6: Oncology | C6: Solid-tumor oncology | D6: puxitatug samrotecan | E6: Phase III | F6: B7-H4 TOP1i antibody-drug conjugate | G6: Solid tumors; Phase III endometrial cancer program | H6: 2026-02-10 | I6: https://www.astrazeneca.com/content/dam/az/Investor_Relations/annual-report-2025/pdf/AstraZeneca_Development_Pipeline_2025.pdf
A7: AstraZeneca | B7: Oncology | C7: Solid-tumor oncology | D7: rilvegostomig | E7: Phase III | F7: PD-1/TIGIT bispecific antibody | G7: NSCLC, HCC, gastric, biliary and other solid tumors | H7: 2026-02-10 | I7: https://www.astrazeneca.com/content/dam/az/Investor_Relations/annual-report-2025/pdf/AstraZeneca_Development_Pipeline_2025.pdf | J7: Multiple combinations and indications counted once under the lead asset.
A8: AstraZeneca | B8: Oncology | C8: Solid-tumor oncology | D8: saruparib | E8: Phase III | F8: PARP1 inhibitor | G8: Prostate and breast cancer programs | H8: 2026-02-10 | I8: https://www.astrazeneca.com/content/dam/az/Investor_Relations/annual-report-2025/pdf/AstraZeneca_Development_Pipeline_2025.pdf | J8: Multiple combinations and indications counted once under the lead asset.
A9: AstraZeneca | B9: Oncology | C9: Solid-tumor oncology | D9: sonesitatug vedotin | E9: Phase III | F9: CLDN18.2 MMAE antibody-drug conjugate | G9: Solid tumors; Phase III gastric cancer program | H9: 2026-02-10 | I9: https://www.astrazeneca.com/content/dam/az/Investor_Relations/annual-report-2025/pdf/AstraZeneca_Development_Pipeline_2025.pdf
A10: AstraZeneca | B10: Oncology | C10: Solid-tumor oncology | D10: tilatamig samrotecan | E10: Phase II | F10: EGFR/cMET TOP1i antibody-drug conjugate | G10: Solid tumors | H10: 2026-02-10 | I10: https://www.astrazeneca.com/content/dam/az/Investor_Relations/annual-report-2025/pdf/AstraZeneca_Development_Pipeline_2025.pdf
A11: AstraZeneca | B11: Oncology | C11: Solid-tumor oncology | D11: torvutatug samrotecan (AZD5335) | E11: Phase III | F11: FR-alpha TOP1i antibody-drug conjugate | G11: Ovarian cancer and other solid tumors | H11: 2026-02-10 | I11: https://www.astrazeneca.com/content/dam/az/Investor_Relations/annual-report-2025/pdf/AstraZeneca_Development_Pipeline_2025.pdf
A12: AstraZeneca | B12: Oncology | C12: Solid-tumor oncology | D12: volrustomig | E12: Phase III | F12: PD-1/CTLA-4 bispecific antibody | G12: NSCLC, cervical, head and neck, colorectal and mesothelioma | H12: 2026-02-10 | I12: https://www.astrazeneca.com/content/dam/az/Investor_Relations/annual-report-2025/pdf/AstraZeneca_Development_Pipeline_2025.pdf | J12: Multiple indications counted once under the lead asset.
A13: AstraZeneca | B13: Oncology | C13: Hematology | D13: AZD0120 | E13: Phase II | F13: CD19/BCMA CAR-T | G13: Multiple myeloma | H13: 2026-02-10 | I13: https://www.astrazeneca.com/content/dam/az/Investor_Relations/annual-report-2025/pdf/AstraZeneca_Development_Pipeline_2025.pdf
A14: AstraZeneca | B14: Oncology | C14: Hematology | D14: AZD0305 | E14: Phase II | F14: GPRC5D MMAE antibody-drug conjugate | G14: Relapsed/refractory multiple myeloma | H14: 2026-02-10 | I14: https://www.astrazeneca.com/content/dam/az/Investor_Relations/annual-report-2025/pdf/AstraZeneca_Development_Pipeline_2025.pdf
A15: AstraZeneca | B15: Oncology | C15: Hematology | D15: AZD3470 | E15: Phase II | F15: PRMT5 inhibitor | G15: Classical Hodgkin lymphoma; also early solid-tumor work | H15: 2026-02-10 | I15: https://www.astrazeneca.com/content/dam/az/Investor_Relations/annual-report-2025/pdf/AstraZeneca_Development_Pipeline_2025.pdf | J15: Classified to hematology based on the disclosed Phase II indication.
A16: AstraZeneca | B16: Oncology | C16: Hematology | D16: surovatamig | E16: Phase III | F16: CD19/CD3 T-cell engager | G16: B-cell malignancies including DLBCL, follicular lymphoma and B-ALL | H16: 2026-02-10 | I16: https://www.astrazeneca.com/content/dam/az/Investor_Relations/annual-report-2025/pdf/AstraZeneca_Development_Pipeline_2025.pdf | J16: Multiple indications counted once under the lead asset.
A17: AstraZeneca | B17: Respiratory & Immunology | C17: Immunology, respiratory & fibrosis | D17: atuliflapon | E17: Phase II | F17: FLAP inhibitor | G17: Asthma | H17: 2026-02-10 | I17: https://www.astrazeneca.com/content/dam/az/Investor_Relations/annual-report-2025/pdf/AstraZeneca_Development_Pipeline_2025.pdf
A18: AstraZeneca | B18: Respiratory & Immunology | C18: Immunology, respiratory & fibrosis | D18: AZD1163 | E18: Phase II | F18: PAD2/4 bispecific antibody | G18: Rheumatoid arthritis | H18: 2026-02-10 | I18: https://www.astrazeneca.com/content/dam/az/Investor_Relations/annual-report-2025/pdf/AstraZeneca_Development_Pipeline_2025.pdf
A19: AstraZeneca | B19: Respiratory & Immunology | C19: Immunology, respiratory & fibrosis | D19: AZD4604 | E19: Phase II | F19: Inhaled JAK1 inhibitor | G19: Asthma | H19: 2026-02-10 | I19: https://www.astrazeneca.com/content/dam/az/Investor_Relations/annual-report-2025/pdf/AstraZeneca_Development_Pipeline_2025.pdf
A20: AstraZeneca | B20: Respiratory & Immunology | C20: Immunology, respiratory & fibrosis | D20: AZD6793 | E20: Phase II | F20: IRAK4 inhibitor | G20: COPD | H20: 2026-02-10 | I20: https://www.astrazeneca.com/content/dam/az/Investor_Relations/annual-report-2025/pdf/AstraZeneca_Development_Pipeline_2025.pdf
A21: AstraZeneca | B21: Respiratory & Immunology | C21: Immunology, respiratory & fibrosis | D21: AZD7798 | E21: Phase II | F21: T-cell-subset-targeting monoclonal antibody | G21: Crohn's disease | H21: 2026-02-10 | I21: https://www.astrazeneca.com/content/dam/az/Investor_Relations/annual-report-2025/pdf/AstraZeneca_Development_Pipeline_2025.pdf
A22: AstraZeneca | B22: Respiratory & Immunology | C22: Immunology, respiratory & fibrosis | D22: AZD8630 | E22: Phase II | F22: Inhaled TSLP Fab | G22: Asthma | H22: 2026-02-10 | I22: https://www.astrazeneca.com/content/dam/az/Investor_Relations/annual-report-2025/pdf/AstraZeneca_Development_Pipeline_2025.pdf
A23: AstraZeneca | B23: Respiratory & Immunology | C23: Immunology, respiratory & fibrosis | D23: tozorakimab | E23: Phase III | F23: IL-33 monoclonal antibody | G23: COPD and severe viral lower respiratory tract disease | H23: 2026-02-10 | I23: https://www.astrazeneca.com/content/dam/az/Investor_Relations/annual-report-2025/pdf/AstraZeneca_Development_Pipeline_2025.pdf
A24: AstraZeneca | B24: CVRM | C24: Cardiovascular | D24: AZD5462 | E24: Phase II | F24: RXFP1 agonist | G24: Heart failure | H24: 2026-02-10 | I24: https://www.astrazeneca.com/content/dam/az/Investor_Relations/annual-report-2025/pdf/AstraZeneca_Development_Pipeline_2025.pdf
A25: AstraZeneca | B25: CVRM | C25: Cardiovascular | D25: baxdrostat | E25: Phase III / registration | F25: Aldosterone synthase inhibitor | G25: Hypertension and primary aldosteronism | H25: 2026-02-10 | I25: https://www.astrazeneca.com/content/dam/az/Investor_Relations/annual-report-2025/pdf/AstraZeneca_Development_Pipeline_2025.pdf | J25: Programs with dapagliflozin counted once under baxdrostat.
A26: AstraZeneca | B26: CVRM | C26: Cardiovascular | D26: laroprovstat | E26: Phase III | F26: PCSK9 inhibitor | G26: Dyslipidemia | H26: 2026-02-10 | I26: https://www.astrazeneca.com/content/dam/az/Investor_Relations/annual-report-2025/pdf/AstraZeneca_Development_Pipeline_2025.pdf
A27: AstraZeneca | B27: CVRM | C27: Renal & metabolic | D27: AZD2389 | E27: Phase II | F27: Anti-fibrotic mechanism | G27: Metabolic dysfunction-associated steatohepatitis | H27: 2026-02-10 | I27: https://www.astrazeneca.com/content/dam/az/Investor_Relations/annual-report-2025/pdf/AstraZeneca_Development_Pipeline_2025.pdf
A28: AstraZeneca | B28: CVRM | C28: Renal & metabolic | D28: AZD6234 | E28: Phase II | F28: Peptide therapy | G28: Chronic weight management | H28: 2026-02-10 | I28: https://www.astrazeneca.com/content/dam/az/Investor_Relations/annual-report-2025/pdf/AstraZeneca_Development_Pipeline_2025.pdf
A29: AstraZeneca | B29: CVRM | C29: Renal & metabolic | D29: AZD9550 + AZD6234 | E29: Phase II | F29: GLP-1/glucagon dual agonist plus amylin agonist | G29: Obesity | H29: 2026-02-10 | I29: https://www.astrazeneca.com/content/dam/az/Investor_Relations/annual-report-2025/pdf/AstraZeneca_Development_Pipeline_2025.pdf | J29: Two-investigational-asset combination counted as one disclosed program.
A30: AstraZeneca | B30: CVRM | C30: Renal & metabolic | D30: balcinrenone / dapagliflozin | E30: Phase III | F30: Mineralocorticoid receptor modulator plus SGLT2 inhibitor | G30: CKD and heart failure with CKD | H30: 2026-02-10 | I30: https://www.astrazeneca.com/content/dam/az/Investor_Relations/annual-report-2025/pdf/AstraZeneca_Development_Pipeline_2025.pdf
A31: AstraZeneca | B31: CVRM | C31: Renal & metabolic | D31: elecoglipron (AZD5004) | E31: Phase II | F31: Oral GLP-1 receptor agonist | G31: Type 2 diabetes and chronic weight management | H31: 2026-02-10 | I31: https://www.astrazeneca.com/content/dam/az/Investor_Relations/annual-report-2025/pdf/AstraZeneca_Development_Pipeline_2025.pdf
A32: AstraZeneca | B32: CVRM | C32: Renal & metabolic | D32: opemalirsen | E32: Phase II | F32: Podocyte-health therapeutic | G32: Nephropathy | H32: 2026-02-10 | I32: https://www.astrazeneca.com/content/dam/az/Investor_Relations/annual-report-2025/pdf/AstraZeneca_Development_Pipeline_2025.pdf
A33: AstraZeneca | B33: CVRM | C33: Renal & metabolic | D33: zibotentan / dapagliflozin | E33: Phase III | F33: Endothelin-A receptor antagonist plus SGLT2 inhibitor | G33: CKD with high proteinuria | H33: 2026-02-10 | I33: https://www.astrazeneca.com/content/dam/az/Investor_Relations/annual-report-2025/pdf/AstraZeneca_Development_Pipeline_2025.pdf
A34: AstraZeneca | B34: Rare Disease | C34: Rare disease | D34: ALXN1920 | E34: Phase II | F34: Kidney-targeted factor H fusion protein | G34: Primary membranous nephropathy | H34: 2026-02-10 | I34: https://www.astrazeneca.com/content/dam/az/Investor_Relations/annual-report-2025/pdf/AstraZeneca_Development_Pipeline_2025.pdf
A35: AstraZeneca | B35: Rare Disease | C35: Rare disease | D35: ALXN2030 | E35: Phase II | F35: Complement C3-targeting siRNA | G35: Antibody-mediated rejection | H35: 2026-02-10 | I35: https://www.astrazeneca.com/content/dam/az/Investor_Relations/annual-report-2025/pdf/AstraZeneca_Development_Pipeline_2025.pdf
A36: AstraZeneca | B36: Rare Disease | C36: Rare disease | D36: ALXN2420 | E36: Phase II | F36: Growth hormone receptor antagonist | G36: Acromegaly | H36: 2026-02-10 | I36: https://www.astrazeneca.com/content/dam/az/Investor_Relations/annual-report-2025/pdf/AstraZeneca_Development_Pipeline_2025.pdf
A37: AstraZeneca | B37: Rare Disease | C37: Rare disease | D37: tarperprumig | E37: Phase II | F37: Kinase inhibitor | G37: ANCA-associated vasculitis | H37: 2026-02-10 | I37: https://www.astrazeneca.com/content/dam/az/Investor_Relations/annual-report-2025/pdf/AstraZeneca_Development_Pipeline_2025.pdf
A38: AstraZeneca | B38: Rare Disease | C38: Rare disease | D38: anselamimab | E38: Phase III / registration | F38: Fibril-reactive monoclonal antibody | G38: AL amyloidosis | H38: 2026-02-10 | I38: https://www.astrazeneca.com/content/dam/az/Investor_Relations/annual-report-2025/pdf/AstraZeneca_Development_Pipeline_2025.pdf
A39: AstraZeneca | B39: Rare Disease | C39: Rare disease | D39: cliramitug | E39: Phase III | F39: Transthyretin depleter | G39: Transthyretin amyloid cardiomyopathy | H39: 2026-02-10 | I39: https://www.astrazeneca.com/content/dam/az/Investor_Relations/annual-report-2025/pdf/AstraZeneca_Development_Pipeline_2025.pdf
A40: AstraZeneca | B40: Rare Disease | C40: Rare disease | D40: efzimfotase alfa | E40: Phase III | F40: Next-generation TNSALP enzyme replacement therapy | G40: Hypophosphatasia | H40: 2026-02-10 | I40: https://www.astrazeneca.com/content/dam/az/Investor_Relations/annual-report-2025/pdf/AstraZeneca_Development_Pipeline_2025.pdf
...

Sheet Overlap_Units
A1: AZ + BMS overlap units - evidence behind bubble counts
A2: One row equals one distinct shared territory/class. Bubble counts are formula-driven from this table. Directness is an analyst-coded input: 1 limited, 2 moderate, 3 strong.
A4: Disease area | B4: Factor | C4: Overlap unit | D4: AZ evidence / programs | E4: BMS evidence / programs | F4: Directness (1-3) | G4: Rationale | H4: AZ source URL | I4: BMS source URL
A5: Solid-tumor oncology | B5: Shared indications | C5: NSCLC | D5: IPH5201; rilvegostomig; volrustomig | E5: pumitamig; iza-bren; navlimetostat; nivolumab + relatlimab HD | F5: 3 | G5: Multiple programs from both companies are being developed in NSCLC, creating direct disease-level overlap. | H5: https://www.astrazeneca.com/content/dam/az/Investor_Relations/annual-report-2025/pdf/AstraZeneca_Development_Pipeline_2025.pdf | I5: https://www.bms.com/assets/bms/us/en-us/pdf/investor-info/doc_presentations/2026/bms-pipeline-february-2026.pdf
A6: Solid-tumor oncology | B6: Shared indications | C6: Prostate cancer | D6: FPI-2265; saruparib | E6: AR ligand-directed degrader | F6: 3 | G6: Both companies have late-stage prostate-cancer programs, although targets and modalities differ. | H6: https://www.astrazeneca.com/content/dam/az/Investor_Relations/annual-report-2025/pdf/AstraZeneca_Development_Pipeline_2025.pdf | I6: https://www.bms.com/assets/bms/us/en-us/pdf/investor-info/doc_presentations/2026/bms-pipeline-february-2026.pdf
A7: Solid-tumor oncology | B7: Shared modalities | C7: Small-molecule targeted therapy | D7: AZD9574; camizestrant; saruparib | E7: navlimetostat; AR ligand-directed degrader | F7: 2 | G7: Both use oral/small-molecule targeted approaches in solid tumors. | H7: https://www.astrazeneca.com/content/dam/az/Investor_Relations/annual-report-2025/pdf/AstraZeneca_Development_Pipeline_2025.pdf | I7: https://www.bms.com/assets/bms/us/en-us/pdf/investor-info/doc_presentations/2026/bms-pipeline-february-2026.pdf
A8: Solid-tumor oncology | B8: Shared modalities | C8: Bispecific / dual-target biologics | D8: rilvegostomig; volrustomig | E8: pumitamig | F8: 3 | G8: Both have late-stage dual-target immuno-oncology biologics. | H8: https://www.astrazeneca.com/content/dam/az/Investor_Relations/annual-report-2025/pdf/AstraZeneca_Development_Pipeline_2025.pdf | I8: https://www.bms.com/assets/bms/us/en-us/pdf/investor-info/doc_presentations/2026/bms-pipeline-february-2026.pdf
A9: Solid-tumor oncology | B9: Shared modalities | C9: Antibody-drug conjugates | D9: puxitatug samrotecan; sonesitatug vedotin; tilatamig samrotecan; torvutatug samrotecan | E9: izalontamab brengitecan | F9: 3 | G9: Both have substantial ADC activity, with AstraZeneca contributing greater breadth. | H9: https://www.astrazeneca.com/content/dam/az/Investor_Relations/annual-report-2025/pdf/AstraZeneca_Development_Pipeline_2025.pdf | I9: https://www.bms.com/assets/bms/us/en-us/pdf/investor-info/doc_presentations/2026/bms-pipeline-february-2026.pdf
A10: Solid-tumor oncology | B10: Shared modalities | C10: Radiopharmaceuticals | D10: FPI-2265 | E10: RYZ101 | F10: 2 | G10: Both have targeted radiopharmaceutical programs, but in different tumor types and targets. | H10: https://www.astrazeneca.com/content/dam/az/Investor_Relations/annual-report-2025/pdf/AstraZeneca_Development_Pipeline_2025.pdf | I10: https://www.bms.com/assets/bms/us/en-us/pdf/investor-info/doc_presentations/2026/bms-pipeline-february-2026.pdf
A11: Solid-tumor oncology | B11: Shared target / mechanism | C11: PD-(L)1-based immuno-oncology | D11: rilvegostomig; volrustomig | E11: pumitamig; nivolumab + relatlimab HD; atigotatug + nivolumab | F11: 3 | G11: Both portfolios use PD-1/PD-L1-centered combinations or multispecific approaches. | H11: https://www.astrazeneca.com/content/dam/az/Investor_Relations/annual-report-2025/pdf/AstraZeneca_Development_Pipeline_2025.pdf | I11: https://www.bms.com/assets/bms/us/en-us/pdf/investor-info/doc_presentations/2026/bms-pipeline-february-2026.pdf
A12: Solid-tumor oncology | B12: Shared target / mechanism | C12: EGFR-directed therapeutics | D12: tilatamig samrotecan | E12: izalontamab brengitecan | F12: 2 | G12: Both have EGFR-directed ADC programs, paired with different second targets. | H12: https://www.astrazeneca.com/content/dam/az/Investor_Relations/annual-report-2025/pdf/AstraZeneca_Development_Pipeline_2025.pdf | I12: https://www.bms.com/assets/bms/us/en-us/pdf/investor-info/doc_presentations/2026/bms-pipeline-february-2026.pdf
A13: Solid-tumor oncology | B13: Stage alignment | C13: Phase II | D13: AZD9574; FPI-2265; IPH5201; tilatamig samrotecan | E13: iza-bren; navlimetostat | F13: 2 | G13: Both companies have Phase II programs in the disease area. | H13: https://www.astrazeneca.com/content/dam/az/Investor_Relations/annual-report-2025/pdf/AstraZeneca_Development_Pipeline_2025.pdf | I13: https://www.bms.com/assets/bms/us/en-us/pdf/investor-info/doc_presentations/2026/bms-pipeline-february-2026.pdf
A14: Solid-tumor oncology | B14: Stage alignment | C14: Phase III / registration | D14: camizestrant; puxitatug samrotecan; rilvegostomig; saruparib; sonesitatug vedotin; torvutatug samrotecan; volrustomig | E14: pumitamig; AR ligand-directed degrader; atigotatug + nivolumab; nivolumab + relatlimab HD; RYZ101 | F14: 3 | G14: Both have broad Phase III/registration portfolios in solid tumors. | H14: https://www.astrazeneca.com/content/dam/az/Investor_Relations/annual-report-2025/pdf/AstraZeneca_Development_Pipeline_2025.pdf | I14: https://www.bms.com/assets/bms/us/en-us/pdf/investor-info/doc_presentations/2026/bms-pipeline-february-2026.pdf
A15: Hematology | B15: Shared indications | C15: Multiple myeloma | D15: AZD0120; AZD0305 | E15: arlo-cel; iberdomide; mezigdomide | F15: 3 | G15: Both companies have multiple late-stage programs in multiple myeloma. | H15: https://www.astrazeneca.com/content/dam/az/Investor_Relations/annual-report-2025/pdf/AstraZeneca_Development_Pipeline_2025.pdf | I15: https://www.bms.com/assets/bms/us/en-us/pdf/investor-info/doc_presentations/2026/bms-pipeline-february-2026.pdf
A16: Hematology | B16: Shared indications | C16: B-cell lymphoma | D16: surovatamig | E16: golcadomide | F16: 3 | G16: Both have Phase III programs in B-cell lymphoma territories. | H16: https://www.astrazeneca.com/content/dam/az/Investor_Relations/annual-report-2025/pdf/AstraZeneca_Development_Pipeline_2025.pdf | I16: https://www.bms.com/assets/bms/us/en-us/pdf/investor-info/doc_presentations/2026/bms-pipeline-february-2026.pdf
... A27: Cardiovascular | B27: Stage alignment | C27: Phase III / registration | D27: baxdrostat; laroprovstat | E27: milvexian | F27: 1 | G27: Both have Phase III programs, but in different cardiovascular indications. | H27: https://www.astrazeneca.com/content/dam/az/Investor_Relations/annual-report-2025/pdf/AstraZeneca_Development_Pipeline_2025.pdf | I27: https://www.bms.com/assets/bms/us/en-us/pdf/investor-info/doc_presentations/2026/bms-pipeline-february-2026.pdf

Sheet Overlap_Matrix
A1: AstraZeneca + BMS: count-based portfolio collision matrix
A2: Counts represent distinct shared territories/classes and are calculated from Overlap_Units. Intensity is the maximum directness score among the units in each cell. Portfolio balance has been removed.
A4: Disease area | B4: Plot label | C4: AZ programs | D4: BMS programs | E4: Combined programs | F4: Shared indications | G4: Indication intensity | H4: Shared modalities | I4: Modality intensity | J4: Shared target / mechanism | K4: Target intensity | L4: Stage alignment | M4: Stage intensity | N4: Strategic read
A5: Solid-tumor oncology | B5: Solid tumors | C5: =COUNTIFS(Asset_Data!$A:$A,"AstraZeneca",Asset_Data!$C:$C,$A5) | D5: =COUNTIFS(Asset_Data!$A:$A,"Bristol Myers Squibb",Asset_Data!$C:$C,$A5) | E5: =SUM(C5:D5) | F5: =COUNTIFS(Overlap_Units!$A:$A,$A5,Overlap_Units!$B:$B,F4) | G5: =IF(F5=0,0,MAXIFS(Overlap_Units!$F:$F,Overlap_Units!$A:$A,$A5,Overlap_Units!$B:$B,F4)) | H5: =COUNTIFS(Overlap_Units!$A:$A,$A5,Overlap_Units!$B:$B,H4) | I5: =IF(H5=0,0,MAXIFS(Overlap_Units!$F:$F,Overlap_Units!$A:$A,$A5,Overlap_Units!$B:$B,H4)) | J5: =COUNTIFS(Overlap_Units!$A:$A,$A5,Overlap_Units!$B:$B,J4) | K5: =IF(J5=0,0,MAXIFS(Overlap_Units!$F:$F,Overlap_Units!$A:$A,$A5,Overlap_Units!$B:$B,J4)) | L5: =COUNTIFS(Overlap_Units!$A:$A,$A5,Overlap_Units!$B:$B,L4) | M5: =IF(L5=0,0,MAXIFS(Overlap_Units!$F:$F,Overlap_Units!$A:$A,$A5,Overlap_Units!$B:$B,L4)) | N5: Strong collision
A6: Hematology | B6: Hematology | C6: =COUNTIFS(Asset_Data!$A:$A,"AstraZeneca",Asset_Data!$C:$C,$A6) | D6: =COUNTIFS(Asset_Data!$A:$A,"Bristol Myers Squibb",Asset_Data!$C:$C,$A6) | E6: =SUM(C6:D6) | F6: =COUNTIFS(Overlap_Units!$A:$A,$A6,Overlap_Units!$B:$B,F4) | G6: =IF(F6=0,0,MAXIFS(Overlap_Units!$F:$F,Overlap_Units!$A:$A,$A6,Overlap_Units!$B:$B,F4)) | H6: =COUNTIFS(Overlap_Units!$A:$A,$A6,Overlap_Units!$B:$B,H4) | I6: =IF(H6=0,0,MAXIFS(Overlap_Units!$F:$F,Overlap_Units!$A:$A,$A6,Overlap_Units!$B:$B,H4)) | J6: =COUNTIFS(Overlap_Units!$A:$A,$A6,Overlap_Units!$B:$B,J4) | K6: =IF(J6=0,0,MAXIFS(Overlap_Units!$F:$F,Overlap_Units!$A:$A,$A6,Overlap_Units!$B:$B,J4)) | L6: =COUNTIFS(Overlap_Units!$A:$A,$A6,Overlap_Units!$B:$B,L4) | M6: =IF(L6=0,0,MAXIFS(Overlap_Units!$F:$F,Overlap_Units!$A:$A,$A6,Overlap_Units!$B:$B,L4)) | N6: Strong collision
A7: Immunology, respiratory & fibrosis | B7: Immunology / resp. / fibrosis | C7: =COUNTIFS(Asset_Data!$A:$A,"AstraZeneca",Asset_Data!$C:$C,$A7) | D7: =COUNTIFS(Asset_Data!$A:$A,"Bristol Myers Squibb",Asset_Data!$C:$C,$A7) | E7: =SUM(C7:D7) | F7: =COUNTIFS(Overlap_Units!$A:$A,$A7,Overlap_Units!$B:$B,F4) | G7: =IF(F7=0,0,MAXIFS(Overlap_Units!$F:$F,Overlap_Units!$A:$A,$A7,Overlap_Units!$B:$B,F4)) | H7: =COUNTIFS(Overlap_Units!$A:$A,$A7,Overlap_Units!$B:$B,H4) | I7: =IF(H7=0,0,MAXIFS(Overlap_Units!$F:$F,Overlap_Units!$A:$A,$A7,Overlap_Units!$B:$B,H4)) | J7: =COUNTIFS(Overlap_Units!$A:$A,$A7,Overlap_Units!$B:$B,J4) | K7: =IF(J7=0,0,MAXIFS(Overlap_Units!$F:$F,Overlap_Units!$A:$A,$A7,Overlap_Units!$B:$B,J4)) | L7: =COUNTIFS(Overlap_Units!$A:$A,$A7,Overlap_Units!$B:$B,L4) | M7: =IF(L7=0,0,MAXIFS(Overlap_Units!$F:$F,Overlap_Units!$A:$A,$A7,Overlap_Units!$B:$B,L4)) | N7: Platform adjacency
A8: Cardiovascular | B8: CV | C8: =COUNTIFS(Asset_Data!$A:$A,"AstraZeneca",Asset_Data!$C:$C,$A8) | D8: =COUNTIFS(Asset_Data!$A:$A,"Bristol Myers Squibb",Asset_Data!$C:$C,$A8) | E8: =SUM(C8:D8) | F8: =COUNTIFS(Overlap_Units!$A:$A,$A8,Overlap_Units!$B:$B,F4) | G8: =IF(F8=0,0,MAXIFS(Overlap_Units!$F:$F,Overlap_Units!$A:$A,$A8,Overlap_Units!$B:$B,F4)) | H8: =COUNTIFS(Overlap_Units!$A:$A,$A8,Overlap_Units!$B:$B,H4) | I8: =IF(H8=0,0,MAXIFS(Overlap_Units!$F:$F,Overlap_Units!$A:$A,$A8,Overlap_Units!$B:$B,H4)) | J8: =COUNTIFS(Overlap_Units!$A:$A,$A8,Overlap_Units!$B:$B,J4) | K8: =IF(J8=0,0,MAXIFS(Overlap_Units!$F:$F,Overlap_Units!$A:$A,$A8,Overlap_Units!$B:$B,J4)) | L8: =COUNTIFS(Overlap_Units!$A:$A,$A8,Overlap_Units!$B:$B,L4) | M8: =IF(L8=0,0,MAXIFS(Overlap_Units!$F:$F,Overlap_Units!$A:$A,$A8,Overlap_Units!$B:$B,L4)) | N8: Narrow adjacency
A9: Rare disease | B9: Rare disease | C9: =COUNTIFS(Asset_Data!$A:$A,"AstraZeneca",Asset_Data!$C:$C,$A9) | D9: =COUNTIFS(Asset_Data!$A:$A,"Bristol Myers Squibb",Asset_Data!$C:$C,$A9) | E9: =SUM(C9:D9) | F9: =COUNTIFS(Overlap_Units!$A:$A,$A9,Overlap_Units!$B:$B,F4) | G9: =IF(F9=0,0,MAXIFS(Overlap_Units!$F:$F,Overlap_Units!$A:$A,$A9,Overlap_Units!$B:$B,F4)) | H9: =COUNTIFS(Overlap_Units!$A:$A,$A9,Overlap_Units!$B:$B,H4) | I9: =IF(H9=0,0,MAXIFS(Overlap_Units!$F:$F,Overlap_Units!$A:$A,$A9,Overlap_Units!$B:$B,H4)) | J9: =COUNTIFS(Overlap_Units!$A:$A,$A9,Overlap_Units!$B:$B,J4) | K9: =IF(J9=0,0,MAXIFS(Overlap_Units!$F:$F,Overlap_Units!$A:$A,$A9,Overlap_Units!$B:$B,J4)) | L9: =COUNTIFS(Overlap_Units!$A:$A,$A9,Overlap_Units!$B:$B,L4) | M9: =IF(L9=0,0,MAXIFS(Overlap_Units!$F:$F,Overlap_Units!$A:$A,$A9,Overlap_Units!$B:$B,L4)) | N9: AZ-led fit
A10: Renal & metabolic | B10: Renal / metabolic | C10: =COUNTIFS(Asset_Data!$A:$A,"AstraZeneca",Asset_Data!$C:$C,$A10) | D10: =COUNTIFS(Asset_Data!$A:$A,"Bristol Myers Squibb",Asset_Data!$C:$C,$A10) | E10: =SUM(C10:D10) | F10: =COUNTIFS(Overlap_Units!$A:$A,$A10,Overlap_Units!$B:$B,F4) | G10: =IF(F10=0,0,MAXIFS(Overlap_Units!$F:$F,Overlap_Units!$A:$A,$A10,Overlap_Units!$B:$B,F4)) | H10: =COUNTIFS(Overlap_Units!$A:$A,$A10,Overlap_Units!$B:$B,H4) | I10: =IF(H10=0,0,MAXIFS(Overlap_Units!$F:$F,Overlap_Units!$A:$A,$A10,Overlap_Units!$B:$B,H4)) | J10: =COUNTIFS(Overlap_Units!$A:$A,$A10,Overlap_Units!$B:$B,J4) | K10: =IF(J10=0,0,MAXIFS(Overlap_Units!$F:$F,Overlap_Units!$A:$A,$A10,Overlap_Units!$B:$B,J4)) | L10: =COUNTIFS(Overlap_Units!$A:$A,$A10,Overlap_Units!$B:$B,L4) | M10: =IF(L10=0,0,MAXIFS(Overlap_Units!$F:$F,Overlap_Units!$A:$A,$A10,Overlap_Units!$B:$B,L4)) | N10: AZ-led fit
A11: Infectious disease | B11: Infectious disease | C11: =COUNTIFS(Asset_Data!$A:$A,"AstraZeneca",Asset_Data!$C:$C,$A11) | D11: =COUNTIFS(Asset_Data!$A:$A,"Bristol Myers Squibb",Asset_Data!$C:$C,$A11) | E11: =SUM(C11:D11) | F11: =COUNTIFS(Overlap_Units!$A:$A,$A11,Overlap_Units!$B:$B,F4) | G11: =IF(F11=0,0,MAXIFS(Overlap_Units!$F:$F,Overlap_Units!$A:$A,$A11,Overlap_Units!$B:$B,F4)) | H11: =COUNTIFS(Overlap_Units!$A:$A,$A11,Overlap_Units!$B:$B,H4) | I11: =IF(H11=0,0,MAXIFS(Overlap_Units!$F:$F,Overlap_Units!$A:$A,$A11,Overlap_Units!$B:$B,H4)) | J11: =COUNTIFS(Overlap_Units!$A:$A,$A11,Overlap_Units!$B:$B,J4) | K11: =IF(J11=0,0,MAXIFS(Overlap_Units!$F:$F,Overlap_Units!$A:$A,$A11,Overlap_Units!$B:$B,J4)) | L11: =COUNTIFS(Overlap_Units!$A:$A,$A11,Overlap_Units!$B:$B,L4) | M11: =IF(L11=0,0,MAXIFS(Overlap_Units!$F:$F,Overlap_Units!$A:$A,$A11,Overlap_Units!$B:$B,L4)) | N11: AZ-led fit
A12: Neuroscience | B12: Neuroscience | C12: =COUNTIFS(Asset_Data!$A:$A,"AstraZeneca",Asset_Data!$C:$C,$A12) | D12: =COUNTIFS(Asset_Data!$A:$A,"Bristol Myers Squibb",Asset_Data!$C:$C,$A12) | E12: =SUM(C12:D12) | F12: =COUNTIFS(Overlap_Units!$A:$A,$A12,Overlap_Units!$B:$B,F4) | G12: =IF(F12=0,0,MAXIFS(Overlap_Units!$F:$F,Overlap_Units!$A:$A,$A12,Overlap_Units!$B:$B,F4)) | H12: =COUNTIFS(Overlap_Units!$A:$A,$A12,Overlap_Units!$B:$B,H4) | I12: =IF(H12=0,0,MAXIFS(Overlap_Units!$F:$F,Overlap_Units!$A:$A,$A12,Overlap_Units!$B:$B,H4)) | J12: =COUNTIFS(Overlap_Units!$A:$A,$A12,Overlap_Units!$B:$B,J4) | K12: =IF(J12=0,0,MAXIFS(Overlap_Units!$F:$F,Overlap_Units!$A:$A,$A12,Overlap_Units!$B:$B,J4)) | L12: =COUNTIFS(Overlap_Units!$A:$A,$A12,Overlap_Units!$B:$B,L4) | M12: =IF(L12=0,0,MAXIFS(Overlap_Units!$F:$F,Overlap_Units!$A:$A,$A12,Overlap_Units!$B:$B,L4)) | N12: BMS-led fit
A15: Definition: overlap count = number of distinct shared territories/classes, not the number of all possible AZ-BMS asset pairs. Late-stage program = unique lead asset in Phase II or Phase III/pivotal/registration.

Sheet Plot_Data
A1: Disease area | B1: Plot label | C1: Factor | D1: Overlap count | E1: Intensity | F1: AZ programs | G1: BMS programs | H1: Relationship
A2: =Overlap_Matrix!A5 | B2: =Overlap_Matrix!B5 | C2: Shared indications | D2: =Overlap_Matrix!F5 | E2: =Overlap_Matrix!G5 | F2: =Overlap_Matrix!C5 | G2: =Overlap_Matrix!D5 | H2: =Overlap_Matrix!N5
A3: =Overlap_Matrix!A5 | B3: =Overlap_Matrix!B5 | C3: Shared modalities | D3: =Overlap_Matrix!H5 | E3: =Overlap_Matrix!I5 | F3: =Overlap_Matrix!C5 | G3: =Overlap_Matrix!D5 | H3: =Overlap_Matrix!N5
A4: =Overlap_Matrix!A5 | B4: =Overlap_Matrix!B5 | C4: Shared target / mechanism | D4: =Overlap_Matrix!J5 | E4: =Overlap_Matrix!K5 | F4: =Overlap_Matrix!C5 | G4: =Overlap_Matrix!D5 | H4: =Overlap_Matrix!N5
A5: =Overlap_Matrix!A5 | B5: =Overlap_Matrix!B5 | C5: Stage alignment | D5: =Overlap_Matrix!L5 | E5: =Overlap_Matrix!M5 | F5: =Overlap_Matrix!C5 | G5: =Overlap_Matrix!D5 | H5: =Overlap_Matrix!N5
A6: =Overlap_Matrix!A6 | B6: =Overlap_Matrix!B6 | C6: Shared indications | D6: =Overlap_Matrix!F6 | E6: =Overlap_Matrix!G6 | F6: =Overlap_Matrix!C6 | G6: =Overlap_Matrix!D6 | H6: =Overlap_Matrix!N6
A7: =Overlap_Matrix!A6 | B7: =Overlap_Matrix!B6 | C7: Shared modalities | D7: =Overlap_Matrix!H6 | E7: =Overlap_Matrix!I6 | F7: =Overlap_Matrix!C6 | G7: =Overlap_Matrix!D6 | H7: =Overlap_Matrix!N6
A8: =Overlap_Matrix!A6 | B8: =Overlap_Matrix!B6 | C8: Shared target / mechanism | D8: =Overlap_Matrix!J6 | E8: =Overlap_Matrix!K6 | F8: =Overlap_Matrix!C6 | G8: =Overlap_Matrix!D6 | H8: =Overlap_Matrix!N6
A9: =Overlap_Matrix!A6 | B9: =Overlap_Matrix!B6 | C9: Stage alignment | D9: =Overlap_Matrix!L6 | E9: =Overlap_Matrix!M6 | F9: =Overlap_Matrix!C6 | G9: =Overlap_Matrix!D6 | H9: =Overlap_Matrix!N6
A10: =Overlap_Matrix!A7 | B10: =Overlap_Matrix!B7 | C10: Shared indications | D10: =Overlap_Matrix!F7 | E10: =Overlap_Matrix!G7 | F10: =Overlap_Matrix!C7 | G10: =Overlap_Matrix!D7 | H10: =Overlap_Matrix!N7
A11: =Overlap_Matrix!A7 | B11: =Overlap_Matrix!B7 | C11: Shared modalities | D11: =Overlap_Matrix!H7 | E11: =Overlap_Matrix!I7 | F11: =Overlap_Matrix!C7 | G11: =Overlap_Matrix!D7 | H11: =Overlap_Matrix!N7
A12: =Overlap_Matrix!A7 | B12: =Overlap_Matrix!B7 | C12: Shared target / mechanism | D12: =Overlap_Matrix!J7 | E12: =Overlap_Matrix!K7 | F12: =Overlap_Matrix!C7 | G12: =Overlap_Matrix!D7 | H12: =Overlap_Matrix!N7
A13: =Overlap_Matrix!A7 | B13: =Overlap_Matrix!B7 | C13: Stage alignment | D13: =Overlap_Matrix!L7 | E13: =Overlap_Matrix!M7 | F13: =Overlap_Matrix!C7 | G13: =Overlap_Matrix!D7 | H13: =Overlap_Matrix!N7
A14: =Overlap_Matrix!A8 | B14: =Overlap_Matrix!B8 | C14: Shared indications | D14: =Overlap_Matrix!F8 | E14: =Overlap_Matrix!G8 | F14: =Overlap_Matrix!C8 | G14: =Overlap_Matrix!D8 | H14: =Overlap_Matrix!N8
A15: =Overlap_Matrix!A8 | B15: =Overlap_Matrix!B8 | C15: Shared modalities | D15: =Overlap_Matrix!H8 | E15: =Overlap_Matrix!I8 | F15: =Overlap_Matrix!C8 | G15: =Overlap_Matrix!D8 | H15: =Overlap_Matrix!N8
A16: =Overlap_Matrix!A8 | B16: =Overlap_Matrix!B8 | C16: Shared target / mechanism | D16: =Overlap_Matrix!J8 | E16: =Overlap_Matrix!K8 | F16: =Overlap_Matrix!C8 | G16: =Overlap_Matrix!D8 | H16: =Overlap_Matrix!N8
A17: =Overlap_Matrix!A8 | B17: =Overlap_Matrix!B8 | C17: Stage alignment | D17: =Overlap_Matrix!L8 | E17: =Overlap_Matrix!M8 | F17: =Overlap_Matrix!C8 | G17: =Overlap_Matrix!D8 | H17: =Overlap_Matrix!N8
A18: =Overlap_Matrix!A9 | B18: =Overlap_Matrix!B9 | C18: Shared indications | D18: =Overlap_Matrix!F9 | E18: =Overlap_Matrix!G9 | F18: =Overlap_Matrix!C9 | G18: =Overlap_Matrix!D9 | H18: =Overlap_Matrix!N9
A19: =Overlap_Matrix!A9 | B19: =Overlap_Matrix!B9 | C19: Shared modalities | D19: =Overlap_Matrix!H9 | E19: =Overlap_Matrix!I9 | F19: =Overlap_Matrix!C9 | G19: =Overlap_Matrix!D9 | H19: =Overlap_Matrix!N9
A20: =Overlap_Matrix!A9 | B20: =Overlap_Matrix!B9 | C20: Shared target / mechanism | D20: =Overlap_Matrix!J9 | E20: =Overlap_Matrix!K9 | F20: =Overlap_Matrix!C9 | G20: =Overlap_Matrix!D9 | H20: =Overlap_Matrix!N9
A21: =Overlap_Matrix!A9 | B21: =Overlap_Matrix!B9 | C21: Stage alignment | D21: =Overlap_Matrix!L9 | E21: =Overlap_Matrix!M9 | F21: =Overlap_Matrix!C9 | G21: =Overlap_Matrix!D9 | H21: =Overlap_Matrix!N9
A22: =Overlap_Matrix!A10 | B22: =Overlap_Matrix!B10 | C22: Shared indications | D22: =Overlap_Matrix!F10 | E22: =Overlap_Matrix!G10 | F22: =Overlap_Matrix!C10 | G22: =Overlap_Matrix!D10 | H22: =Overlap_Matrix!N10
A23: =Overlap_Matrix!A10 | B23: =Overlap_Matrix!B10 | C23: Shared modalities | D23: =Overlap_Matrix!H10 | E23: =Overlap_Matrix!I10 | F23: =Overlap_Matrix!C10 | G23: =Overlap_Matrix!D10 | H23: =Overlap_Matrix!N10
A24: =Overlap_Matrix!A10 | B24: =Overlap_Matrix!B10 | C24: Shared target / mechanism | D24: =Overlap_Matrix!J10 | E24: =Overlap_Matrix!K10 | F24: =Overlap_Matrix!C10 | G24: =Overlap_Matrix!D10 | H24: =Overlap_Matrix!N10
A25: =Overlap_Matrix!A10 | B25: =Overlap_Matrix!B10 | C25: Stage alignment | D25: =Overlap_Matrix!L10 | E25: =Overlap_Matrix!M10 | F25: =Overlap_Matrix!C10 | G25: =Overlap_Matrix!D10 | H25: =Overlap_Matrix!N10
A26: =Overlap_Matrix!A11 | B26: =Overlap_Matrix!B11 | C26: Shared indications | D26: =Overlap_Matrix!F11 | E26: =Overlap_Matrix!G11 | F26: =Overlap_Matrix!C11 | G26: =Overlap_Matrix!D11 | H26: =Overlap_Matrix!N11
A27: =Overlap_Matrix!A11 | B27: =Overlap_Matrix!B11 | C27: Shared modalities | D27: =Overlap_Matrix!H11 | E27: =Overlap_Matrix!I11 | F27: =Overlap_Matrix!C11 | G27: =Overlap_Matrix!D11 | H27: =Overlap_Matrix!N11
A28: =Overlap_Matrix!A11 | B28: =Overlap_Matrix!B11 | C28: Shared target / mechanism | D28: =Overlap_Matrix!J11 | E28: =Overlap_Matrix!K11 | F28: =Overlap_Matrix!C11 | G28: =Overlap_Matrix!D11 | H28: =Overlap_Matrix!N11
A29: =Overlap_Matrix!A11 | B29: =Overlap_Matrix!B11 | C29: Stage alignment | D29: =Overlap_Matrix!L11 | E29: =Overlap_Matrix!M11 | F29: =Overlap_Matrix!C11 | G29: =Overlap_Matrix!D11 | H29: =Overlap_Matrix!N11
A30: =Overlap_Matrix!A12 | B30: =Overlap_Matrix!B12 | C30: Shared indications | D30: =Overlap_Matrix!F12 | E30: =Overlap_Matrix!G12 | F30: =Overlap_Matrix!C12 | G30: =Overlap_Matrix!D12 | H30: =Overlap_Matrix!N12
A31: =Overlap_Matrix!A12 | B31: =Overlap_Matrix!B12 | C31: Shared modalities | D31: =Overlap_Matrix!H12 | E31: =Overlap_Matrix!I12 | F31: =Overlap_Matrix!C12 | G31: =Overlap_Matrix!D12 | H31: =Overlap_Matrix!N12
A32: =Overlap_Matrix!A12 | B32: =Overlap_Matrix!B12 | C32: Shared target / mechanism | D32: =Overlap_Matrix!J12 | E32: =Overlap_Matrix!K12 | F32: =Overlap_Matrix!C12 | G32: =Overlap_Matrix!D12 | H32: =Overlap_Matrix!N12
A33: =Overlap_Matrix!A12 | B33: =Overlap_Matrix!B12 | C33: Stage alignment | D33: =Overlap_Matrix!L12 | E33: =Overlap_Matrix!M12 | F33: =Overlap_Matrix!C12 | G33: =Overlap_Matrix!D12 | H33: =Overlap_Matrix!N12

Sheet Visual_Settings
A1: Visual settings and encoding
A3: Element | B3: Hex | C3: Use | D3: Notes
A4: AstraZeneca primary | B4: #7A1F63 | C4: Stacked bar | D4: Logo-inspired plum
A5: AstraZeneca accent | B5: #D7A900 | C5: Thin bar/legend accent | D5: Logo-inspired gold
A6: BMS primary | B6: #263B73 | C6: Stacked bar | D6: Logo-inspired navy
A7: BMS accent | B7: #76519A | C7: Thin bar/legend accent | D7: Hand-mark-inspired violet
A8: Overlap - limited | B8: #F7D3D0 | C8: Bubble fill | D8: Low directness
A9: Overlap - moderate | B9: #ED756D | C9: Bubble fill | D9: Medium directness
A10: Overlap - strong | B10: #C51F36 | C10: Bubble fill | D10: High directness
A11: Bubble outline | B11: #8E1829 | C11: Bubble border | D11: Consistent red boundary
A12: Page background | B12: #F4F1EC | C12: Canvas | D12: Warm neutral
A13: Card background | B13: #FFFFFF | C13: Main panel | D13: White
A14: Primary text | B14: #182230 | C14: Text | D14: Dark ink
A17: Encoding definitions
A18: Stacked-bar height | B18: Number of unique late-stage programs by company and disease area
A19: Bubble label + size | B19: Number of distinct shared overlap units in the corresponding disease area and portfolio dimension
A20: Bubble red tone | B20: Analyst-coded directness: 1 limited, 2 moderate, 3 strong
A21: Hollow circle | B21: No identified overlap unit under the current normalization

Sheet Summary
A1: Portfolio summary (formula-driven)
A3: Normalized area | B3: AstraZeneca | C3: Bristol Myers Squibb | D3: Combined | E3: Portfolio relationship
A4: Solid-tumor oncology | B4: =COUNTIFS(Asset_Data!$A:$A,"AstraZeneca",Asset_Data!$C:$C,$A4) | C4: =COUNTIFS(Asset_Data!$A:$A,"Bristol Myers Squibb",Asset_Data!$C:$C,$A4) | D4: =SUM(B4:C4) | E4: =IF(AND(B4>0,C4>0),"Shared territory","One-sided strength")
A5: Immunology, respiratory & fibrosis | B5: =COUNTIFS(Asset_Data!$A:$A,"AstraZeneca",Asset_Data!$C:$C,$A5) | C5: =COUNTIFS(Asset_Data!$A:$A,"Bristol Myers Squibb",Asset_Data!$C:$C,$A5) | D5: =SUM(B5:C5) | E5: =IF(AND(B5>0,C5>0),"Shared territory","One-sided strength")
A6: Hematology | B6: =COUNTIFS(Asset_Data!$A:$A,"AstraZeneca",Asset_Data!$C:$C,$A6) | C6: =COUNTIFS(Asset_Data!$A:$A,"Bristol Myers Squibb",Asset_Data!$C:$C,$A6) | D6: =SUM(B6:C6) | E6: =IF(AND(B6>0,C6>0),"Shared territory","One-sided strength")
A7: Cardiovascular | B7: =COUNTIFS(Asset_Data!$A:$A,"AstraZeneca",Asset_Data!$C:$C,$A7) | C7: =COUNTIFS(Asset_Data!$A:$A,"Bristol Myers Squibb",Asset_Data!$C:$C,$A7) | D7: =SUM(B7:C7) | E7: =IF(AND(B7>0,C7>0),"Shared territory","One-sided strength")
A8: Rare disease | B8: =COUNTIFS(Asset_Data!$A:$A,"AstraZeneca",Asset_Data!$C:$C,$A8) | C8: =COUNTIFS(Asset_Data!$A:$A,"Bristol Myers Squibb",Asset_Data!$C:$C,$A8) | D8: =SUM(B8:C8) | E8: =IF(AND(B8>0,C8>0),"Shared territory","One-sided strength")
A9: Renal & metabolic | B9: =COUNTIFS(Asset_Data!$A:$A,"AstraZeneca",Asset_Data!$C:$C,$A9) | C9: =COUNTIFS(Asset_Data!$A:$A,"Bristol Myers Squibb",Asset_Data!$C:$C,$A9) | D9: =SUM(B9:C9) | E9: =IF(AND(B9>0,C9>0),"Shared territory","One-sided strength")
A10: Infectious disease | B10: =COUNTIFS(Asset_Data!$A:$A,"AstraZeneca",Asset_Data!$C:$C,$A10) | C10: =COUNTIFS(Asset_Data!$A:$A,"Bristol Myers Squibb",Asset_Data!$C:$C,$A10) | D10: =SUM(B10:C10) | E10: =IF(AND(B10>0,C10>0),"Shared territory","One-sided strength")
A11: Neuroscience | B11: =COUNTIFS(Asset_Data!$A:$A,"AstraZeneca",Asset_Data!$C:$C,$A11) | C11: =COUNTIFS(Asset_Data!$A:$A,"Bristol Myers Squibb",Asset_Data!$C:$C,$A11) | D11: =SUM(B11:C11) | E11: =IF(AND(B11>0,C11>0),"Shared territory","One-sided strength")
A12: Total | B12: =SUM(B4:B11) | C12: =SUM(C4:C11) | D12: =SUM(D4:D11)

Sheet LinkedIn_Draft
A1: LinkedIn post draft
A3: The AstraZeneca–BMS rumor appears to be off the table. But the portfolio thought experiment is still interesting. I mapped the companies’ Phase II/III investigational portfolios using matched February 2026 company disclosures. The result looks less like a simple “R&D machine” and more like a mix of portfolio fit and collision. The collision zone is oncology. Across the mapped portfolio, the two companies have 18 solid-tumor programs and 8 hematology programs. Both are active in immuno-oncology and lung cancer, while the broader pipelines span ADCs, bispecifics, radiopharmaceuticals, cell therapy and targeted protein degradation. The complementarity is mostly outside oncology. AstraZeneca contributes much more breadth in rare disease, renal/metabolic disease and infectious disease. BMS adds a distinct neuroscience position, while both companies also overlap in immunology/respiratory/fibrosis and cardiovascular disease. The real integration question would not be whether the combined company had enough assets. It would be which programs, platforms, teams and partnerships would survive portfolio prioritization. More breadth creates more optionality—but also more duplication and harder choices. My takeaway: the strategic value would depend less on adding the two pipelines together, and more on how aggressively management rationalized the overlap without disrupting the science that created it. What would you scrutinize first: portfolio overlap, patent cliffs or integration risk? Data note: unique lead investigational assets/programs in Phase II or III/pivotal/registration; matched AstraZeneca (Feb. 10, 2026) and BMS (Feb. 5, 2026) disclosures; approved-indication expansions and significant life-cycle-management programs excluded.
A5: Optional shorter opening
A6: The rumor may be dead. The portfolio question is not: would AstraZeneca + BMS create strategic fit—or force a wave of R&D rationalization?
A8: Suggested hashtags
A9: #Pharma #Biotech #DrugDevelopment #Oncology #Strategy #MergersAndAcquisitions

Sheet Sources
A1: Source | B1: Date | C1: Use | D1: URL
A2: AstraZeneca development pipeline | B2: 10 Feb 2026 | C2: Primary data for AstraZeneca Phase II and Phase III/pivotal/registration assets | D2: https://www.astrazeneca.com/content/dam/az/Investor_Relations/annual-report-2025/pdf/AstraZeneca_Development_Pipeline_2025.pdf
A3: BMS development portfolio | B3: 5 Feb 2026 | C3: Primary data for BMS Phase II and Phase III investigational compounds | D3: https://annual-report.bms.com/assets/bms-ar/documents/2025/2025-bms-development-portfolio.pdf
A4: AstraZeneca current pipeline page | B4: 27 Jul 2026 | C4: Current context; not used for matched-snapshot counts | D4: https://www.astrazeneca.com/our-therapy-areas/pipeline.html
A5: BMS current pipeline page | B5: 30 Jul 2026 | C5: Current context; not used for matched-snapshot counts | D5: https://www.bms.com/research-and-development/pipeline.html
A6: Reuters report on deal discussions | B6: 5 Aug 2026 | C6: Current-event caveat for post framing | D6: https://www.reuters.com/business/healthcare-pharmaceuticals/no-discussions-over-astrazeneca-bristol-myers-deal-senior-source-says-2026-08-05/

Sheet Infographic
A1: LinkedIn infographic - stacked footprint + count-based lollipop matrix
A2: Bars use logo-inspired company colors; bubbles use a red directness scale.

Sheet Program_Details
A1: Disease area | B1: Overlap indication | C1: Company | D1: Program | E1: Pipeline stage | F1: Representative modality / mechanism | G1: ClinicalTrials.gov ID | H1: Representative trial | I1: Potential launch indication (analyst scenario) | J1: Clinical setting / line of therapy | K1: Primary completion date | L1: Primary completion year | M1: Launch lag - low (years) | N1: Launch lag - high (years) | O1: Illustrative launch start | P1: Illustrative launch end | Q1: Illustrative launch window | R1: Historical sales of asset | S1: Commercial benchmark IDs | T1: Trial URL | U1: Pipeline source URL | V1: Notes
A2: Cardiovascular | B2: Heart failure | C2: AstraZeneca | D2: AZD5462 | E2: Phase IIb | F2: RXFP1 agonist | G2: NCT06299826 | H2: LUMINARA | I2: Chronic heart failure | J2: Stable chronic heart failure; mechanism-focused proof of concept | K2: 46063 | L2: =YEAR(K2) | M2: 3 | N2: 5 | O2: =IF(OR(L2="",M2=""),"",L2+M2) | P2: =IF(OR(L2="",N2=""),"",L2+N2) | Q2: =IF(O2="","Not estimated",TEXT(O2,"0")&"-"&TEXT(P2,"0")) | R2: Not launched - no historical sales | S2: HF_CAMZYOS_2025 | T2: https://clinicaltrials.gov/study/NCT06299826 | U2: https://www.astrazeneca.com/content/dam/az/Investor_Relations/annual-report-2025/pdf/AstraZeneca_Development_Pipeline_2025.pdf | V2: Phase IIb; no pivotal launch assumption is implied.
A3: Cardiovascular | B3: Heart failure | C3: Bristol Myers Squibb | D3: MYK-224 | E3: Phase IIa | F3: Cardiac myosin inhibitor | G3: NCT06122779 | H3: AURORA-HFpEF | I3: Heart failure with preserved ejection fraction | J3: Symptomatic HFpEF; randomized placebo-controlled proof of concept | K3: 46206 | L3: =YEAR(K3) | M3: 3 | N3: 5 | O3: =IF(OR(L3="",M3=""),"",L3+M3) | P3: =IF(OR(L3="",N3=""),"",L3+N3) | Q3: =IF(O3="","Not estimated",TEXT(O3,"0")&"-"&TEXT(P3,"0")) | R3: Not launched - no historical sales | S3: HF_CAMZYOS_2025 | T3: https://clinicaltrials.gov/study/NCT06122779 | U3: https://annual-report.bms.com/assets/bms-ar/documents/2025/2025-bms-development-portfolio.pdf | V3: Cardiac myosin inhibitor; not the same indication as approved Camzyos.
A4: Hematology | B4: B-cell lymphoma | C4: AstraZeneca | D4: surovatamig | E4: Phase III | F4: CD19/CD3 T-cell engager | G4: NCT06549595 | H4: SOUNDTRACK-F1 | I4: Previously untreated follicular lymphoma | J4: First-line; surovatamig plus rituximab versus chemoimmunotherapy | K4: 48178 | L4: =YEAR(K4) | M4: 1 | N4: 2 | O4: =IF(OR(L4="",M4=""),"",L4+M4) | P4: =IF(OR(L4="",N4=""),"",L4+N4) | Q4: =IF(O4="","Not estimated",TEXT(O4,"0")&"-"&TEXT(P4,"0")) | R4: Not launched - no historical sales | S4: LYMPHOMA_BREYANZI_2025 | T4: https://clinicaltrials.gov/study/NCT06549595 | U4: https://www.astrazeneca.com/content/dam/az/Investor_Relations/annual-report-2025/pdf/AstraZeneca_Development_Pipeline_2025.pdf | V4: Representative pivotal study in the B-cell lymphoma territory.
A5: Hematology | B5: B-cell lymphoma | C5: Bristol Myers Squibb | D5: golcadomide | E5: Phase III | F5: CELMoD / targeted protein degradation | G5: NCT06356129 | H5: GOLSEEK-1 | I5: Previously untreated high-risk large B-cell lymphoma | J5: First-line; golcadomide plus R-CHOP | K5: 46979 | L5: =YEAR(K5) | M5: 1 | N5: 2 | O5: =IF(OR(L5="",M5=""),"",L5+M5) | P5: =IF(OR(L5="",N5=""),"",L5+N5) | Q5: =IF(O5="","Not estimated",TEXT(O5,"0")&"-"&TEXT(P5,"0")) | R5: Not launched - no historical sales | S5: LYMPHOMA_BREYANZI_2025 | T5: https://clinicaltrials.gov/study/NCT06356129 | U5: https://annual-report.bms.com/assets/bms-ar/documents/2025/2025-bms-development-portfolio.pdf | V5: Representative Phase III study; additional follicular lymphoma work is underway.
A6: Hematology | B6: Multiple myeloma | C6: AstraZeneca | D6: AZD0120 | E6: Phase Ib/II | F6: CD19/BCMA CAR-T | G6: NCT05850234 | H6: DURGA-1 | I6: Relapsed/refractory multiple myeloma | J6: At least three prior lines; CD19/BCMA dual CAR-T | K6: 46630 | L6: =YEAR(K6) | M6: 4 | N6: 6 | O6: =IF(OR(L6="",M6=""),"",L6+M6) | P6: =IF(OR(L6="",N6=""),"",L6+N6) | Q6: =IF(O6="","Not estimated",TEXT(O6,"0")&"-"&TEXT(P6,"0")) | R6: Not launched - no historical sales | S6: MM_REVLIMID_2021; MM_POMALYST_2021 | T6: https://clinicaltrials.gov/study/NCT05850234 | U6: https://www.astrazeneca.com/content/dam/az/Investor_Relations/annual-report-2025/pdf/AstraZeneca_Development_Pipeline_2025.pdf | V6: Early-stage CAR-T program; launch window is highly uncertain.
A7: Hematology | B7: Multiple myeloma | C7: AstraZeneca | D7: AZD0305 | E7: Phase I/II | F7: GPRC5D MMAE antibody-drug conjugate | G7: NCT06106945 | H7: Modular Phase I/II study | I7: Multiple myeloma | J7: Monotherapy and combination dose escalation/expansion | K7: 46615 | L7: =YEAR(K7) | M7: 4 | N7: 6 | O7: =IF(OR(L7="",M7=""),"",L7+M7) | P7: =IF(OR(L7="",N7=""),"",L7+N7) | Q7: =IF(O7="","Not estimated",TEXT(O7,"0")&"-"&TEXT(P7,"0")) | R7: Not launched - no historical sales | S7: MM_REVLIMID_2021; MM_POMALYST_2021 | T7: https://clinicaltrials.gov/study/NCT06106945 | U7: https://www.astrazeneca.com/content/dam/az/Investor_Relations/annual-report-2025/pdf/AstraZeneca_Development_Pipeline_2025.pdf | V7: GPRC5D ADC; launch window is highly uncertain.
A8: Hematology | B8: Multiple myeloma | C8: Bristol Myers Squibb | D8: arlo-cel | E8: Phase III | F8: GPRC5D-directed autologous CAR-T | G8: NCT06615479 | H8: QUINTESSENTIAL-2 | I8: Relapsed/refractory, lenalidomide-exposed multiple myeloma | J8: Relapsed/refractory setting; versus standard regimens | K8: 46751 | L8: =YEAR(K8) | M8: 1 | N8: 2 | O8: =IF(OR(L8="",M8=""),"",L8+M8) | P8: =IF(OR(L8="",N8=""),"",L8+N8) | Q8: =IF(O8="","Not estimated",TEXT(O8,"0")&"-"&TEXT(P8,"0")) | R8: Not launched - no historical sales | S8: MM_REVLIMID_2021; MM_POMALYST_2021 | T8: https://clinicaltrials.gov/study/NCT06615479 | U8: https://annual-report.bms.com/assets/bms-ar/documents/2025/2025-bms-development-portfolio.pdf | V8: GPRC5D-directed CAR-T; program also has a later-line Phase II study.
A9: Hematology | B9: Multiple myeloma | C9: Bristol Myers Squibb | D9: iberdomide | E9: Phase III | F9: CELMoD / targeted protein degradation | G9: NCT05827016 | H9: EXCALIBER-Maintenance | I9: Newly diagnosed multiple myeloma maintenance | J9: Maintenance following autologous stem-cell transplant | K9: 47192 | L9: =YEAR(K9) | M9: 1 | N9: 2 | O9: =IF(OR(L9="",M9=""),"",L9+M9) | P9: =IF(OR(L9="",N9=""),"",L9+N9) | Q9: =IF(O9="","Not estimated",TEXT(O9,"0")&"-"&TEXT(P9,"0")) | R9: Not launched - no historical sales | S9: MM_REVLIMID_2021; MM_POMALYST_2021 | T9: https://clinicaltrials.gov/study/NCT05827016 | U9: https://annual-report.bms.com/assets/bms-ar/documents/2025/2025-bms-development-portfolio.pdf | V9: Representative Phase III study; the asset has a broader development program.
A10: Hematology | B10: Multiple myeloma | C10: Bristol Myers Squibb | D10: mezigdomide | E10: Phase III | F10: CELMoD / targeted protein degradation | G10: NCT05552976 | H10: SUCCESSOR-2 | I10: Relapsed/refractory multiple myeloma | J10: Mezigdomide-carfilzomib-dexamethasone versus carfilzomib-dexamethasone | K10: 46221 | L10: =YEAR(K10) | M10: 1 | N10: 2 | O10: =IF(OR(L10="",M10=""),"",L10+M10) | P10: =IF(OR(L10="",N10=""),"",L10+N10) | Q10: =IF(O10="","Not estimated",TEXT(O10,"0")&"-"&TEXT(P10,"0")) | R10: Not launched - no historical sales | S10: MM_REVLIMID_2021; MM_POMALYST_2021 | T10: https://clinicaltrials.gov/study/NCT05552976 | U10: https://annual-report.bms.com/assets/bms-ar/documents/2025/2025-bms-development-portfolio.pdf | V10: BMS reported positive Phase III results in 2026; launch timing remains an analyst scenario.
A11: Solid-tumor oncology | B11: NSCLC | C11: AstraZeneca | D11: IPH5201 | E11: Phase II | F11: CD39 monoclonal antibody | G11: NCT05742607 | H11: MATISSE | I11: Resectable stage II-IIIA NSCLC | J11: Untreated; neoadjuvant therapy before surgery followed by adjuvant therapy | K11: 2025-06 | L11: =IF(K11="","",VALUE(LEFT(K11,4))) | M11: 3 | N11: 5 | O11: =IF(OR(L11="",M11=""),"",L11+M11) | P11: =IF(OR(L11="",N11=""),"",L11+N11) | Q11: =IF(O11="","Not estimated",TEXT(O11,"0")&"-"&TEXT(P11,"0")) | R11: Not launched - no historical sales | S11: NSCLC_TAGRISSO_2025; NSCLC_OPDIVO_2025 | T11: https://clinicaltrials.gov/study/NCT05742607 | U11: https://www.astrazeneca.com/content/dam/az/Investor_Relations/annual-report-2025/pdf/AstraZeneca_Development_Pipeline_2025.pdf | V11: Early-stage study; no pivotal launch assumption is implied.
A12: Solid-tumor oncology | B12: NSCLC | C12: AstraZeneca | D12: rilvegostomig | E12: Phase III | F12: PD-1/TIGIT bispecific antibody | G12: NCT06692738 | H12: ARTEMIDE-Lung02 | I12: Metastatic squamous NSCLC, PD-L1 >=1% | J12: First-line; rilvegostomig plus platinum chemotherapy | K12: 47154 | L12: =YEAR(K12) | M12: 1 | N12: 2 | O12: =IF(OR(L12="",M12=""),"",L12+M12) | P12: =IF(OR(L12="",N12=""),"",L12+N12) | Q12: =IF(O12="","Not estimated",TEXT(O12,"0")&"-"&TEXT(P12,"0")) | R12: Not launched - no historical sales | S12: NSCLC_TAGRISSO_2025; NSCLC_OPDIVO_2025 | T12: https://clinicaltrials.gov/study/NCT06692738 | U12: https://www.astrazeneca.com/content/dam/az/Investor_Relations/annual-report-2025/pdf/AstraZeneca_Development_Pipeline_2025.pdf | V12: Representative pivotal study; the asset has additional NSCLC programs.
A13: Solid-tumor oncology | B13: NSCLC | C13: AstraZeneca | D13: volrustomig | E13: Phase III | F13: PD-1/CTLA-4 bispecific antibody | G13: NCT05984277 | H13: eVOLVE-Lung02 | I13: Metastatic NSCLC, PD-L1 <50% | J13: First-line; volrustomig plus histology-specific chemotherapy | K13: 46867 | L13: =YEAR(K13) | M13: 1 | N13: 2 | O13: =IF(OR(L13="",M13=""),"",L13+M13) | P13: =IF(OR(L13="",N13=""),"",L13+N13) | Q13: =IF(O13="","Not estimated",TEXT(O13,"0")&"-"&TEXT(P13,"0")) | R13: Not launched - no historical sales | S13: NSCLC_TAGRISSO_2025; NSCLC_OPDIVO_2025 | T13: https://clinicaltrials.gov/study/NCT05984277 | U13: https://www.astrazeneca.com/content/dam/az/Investor_Relations/annual-report-2025/pdf/AstraZeneca_Development_Pipeline_2025.pdf | V13: Representative pivotal study.
A14: Solid-tumor oncology | B14: NSCLC | C14: Bristol Myers Squibb | D14: izalontamab brengitecan (iza-bren) | E14: Phase II/III | F14: EGFR x HER3 bispecific antibody-drug conjugate | G14: NCT07100080 | H14: IZABRIGHT-Lung01 | I14: EGFR-mutated NSCLC after EGFR-TKI failure | J14: Post-EGFR TKI; compared with platinum-pemetrexed | K14: 47102 | L14: =YEAR(K14) | M14: 1 | N14: 3 | O14: =IF(OR(L14="",M14=""),"",L14+M14) | P14: =IF(OR(L14="",N14=""),"",L14+N14) | Q14: =IF(O14="","Not estimated",TEXT(O14,"0")&"-"&TEXT(P14,"0")) | R14: Not launched - no historical sales | S14: NSCLC_TAGRISSO_2025; NSCLC_OPDIVO_2025 | T14: https://clinicaltrials.gov/study/NCT07100080 | U14: https://annual-report.bms.com/assets/bms-ar/documents/2025/2025-bms-development-portfolio.pdf | V14: Phase II/III design.
A15: Solid-tumor oncology | B15: NSCLC | C15: Bristol Myers Squibb | D15: navlimetostat | E15: Phase II | F15: PRMT5 inhibitor | G15: NCT06855771 | H15: MountainTAP-9 | I15: MTAP-deleted advanced or metastatic NSCLC | J15: Previously treated; after progression on prior therapies | K15: 47116 | L15: =YEAR(K15) | M15: 3 | N15: 5 | O15: =IF(OR(L15="",M15=""),"",L15+M15) | P15: =IF(OR(L15="",N15=""),"",L15+N15) | Q15: =IF(O15="","Not estimated",TEXT(O15,"0")&"-"&TEXT(P15,"0")) | R15: Not launched - no historical sales | S15: NSCLC_TAGRISSO_2025; NSCLC_OPDIVO_2025 | T15: https://clinicaltrials.gov/study/NCT06855771 | U15: https://annual-report.bms.com/assets/bms-ar/documents/2025/2025-bms-development-portfolio.pdf | V15: Phase II; a registrational path is not assumed.
A16: Solid-tumor oncology | B16: NSCLC | C16: Bristol Myers Squibb | D16: nivolumab + relatlimab HD | E16: Phase III | F16: PD-1 plus LAG-3 immuno-oncology combination | G16: NCT06561386 | H16: RELATIVITY-1093 | I16: Stage IV/recurrent nonsquamous NSCLC, PD-L1 >=1% | J16: First-line; nivolumab-relatlimab fixed dose plus chemotherapy | K16: 47694 | L16: =YEAR(K16) | M16: 1 | N16: 2 | O16: =IF(OR(L16="",M16=""),"",L16+M16) | P16: =IF(OR(L16="",N16=""),"",L16+N16) | Q16: =IF(O16="","Not estimated",TEXT(O16,"0")&"-"&TEXT(P16,"0")) | R16: Not launched - no historical sales | S16: NSCLC_TAGRISSO_2025; NSCLC_OPDIVO_2025 | T16: https://clinicaltrials.gov/study/NCT06561386 | U16: https://annual-report.bms.com/assets/bms-ar/documents/2025/2025-bms-development-portfolio.pdf | V16: Potential label expansion of an approved combination; counted here as an investigational program in the matched snapshot.
A17: Solid-tumor oncology | B17: NSCLC | C17: Bristol Myers Squibb | D17: pumitamig | E17: Phase III | F17: PD-L1 x VEGF-A bispecific antibody | G17: NCT07361510 | H17: ROSETTA Lung-202 | I17: Advanced NSCLC, PD-L1 >=50% | J17: First-line monotherapy versus pembrolizumab | K17: 48135 | L17: =YEAR(K17) | M17: 1 | N17: 2 | O17: =IF(OR(L17="",M17=""),"",L17+M17) | P17: =IF(OR(L17="",N17=""),"",L17+N17) | Q17: =IF(O17="","Not estimated",TEXT(O17,"0")&"-"&TEXT(P17,"0")) | R17: Not launched - no historical sales | S17: NSCLC_TAGRISSO_2025; NSCLC_OPDIVO_2025 | T17: https://clinicaltrials.gov/study/NCT07361510 | U17: https://annual-report.bms.com/assets/bms-ar/documents/2025/2025-bms-development-portfolio.pdf | V17: Representative Phase III study; later timing reflects the currently posted trial schedule.
