Workbook

Sheet Website_README
A1: Interactive website package - data and methodology
A3: Package purpose | B3: Back-up data for the GitHub Pages website. The interactive chart links each overlap bubble to the exact overlap units and relevant programs.
A4: Matched portfolio snapshot | B4: AstraZeneca 10 Feb 2026 and BMS 5 Feb 2026 pipeline disclosures.
A5: Late-stage program definition | B5: Unique lead investigational asset in Phase II or Phase III/pivotal/registration development; approved-indication expansions and major lifecycle-management programs excluded from the core count.
A6: Overlap count definition | B6: Number of distinct shared indication territories, modality classes, target/mechanism themes, or development-stage bands - not all possible AZ-BMS asset-pair permutations.
A7: Launch window | B7: Illustrative analyst scenario calculated from trial primary-completion year plus a stage-specific lag. It is not company guidance, a probability-adjusted forecast, or a regulatory prediction.
A8: Historical sales | B8: Investigational assets have no historical sales. The Commercial_Benchmarks sheet provides company-reported brand revenue for scale context; figures are generally not indication-specific.
A9: Website deployment | B9: Upload the package contents to a GitHub repository and enable GitHub Pages from the main branch / root folder. No build step is required.
A11: Fit-vs-collision matrix | B11: Analyst-normalized indication-territory × modality-family map. AZ-only/BMS-only cells show complementarity; overlap cells show collision. The map does not capture earlier-stage, marketed or undisclosed programs.
A13: v4 update | B13: Program rows now show approved brands or marketed components where available. Sales trend cards separate reported history (solid) from analyst projections (dashed), with disclosed patent / exclusivity events reflected in the scenarios.

Sheet README
A1: AstraZeneca + BMS: Portfolio Fit—or Collision?
A3: Purpose
A4: Backup workbook for a LinkedIn post examining where AstraZeneca and Bristol Myers Squibb have overlapping versus complementary late-stage R&D portfolios.
A7: Headline findings
A8: 1. The shared areas contain 41 of 62 mapped programs (66%), concentrated in solid-tumor oncology, hematology, immunology/respiratory/fibrosis and cardiovascular disease.
A9: 2. Oncology is the clearest collision zone: 18 solid-tumor programs plus 8 hematology programs across the two companies.
A10: 3. Complementarity is strongest outside oncology: AstraZeneca adds rare disease, renal/metabolic and infectious-disease breadth; BMS adds a distinct neuroscience foothold.
A11: 4. Counts show portfolio breadth—not program quality, probability of success, revenue potential, target-level duplication or antitrust risk.
A14: Methodology
A15: Snapshot dates | B15: AstraZeneca: 10 Feb 2026; BMS: 5 Feb 2026. Matching annual-report snapshots were used to improve comparability.
A16: Included | B16: Lead investigational assets or disclosed lead programs in Phase II or Phase III/pivotal/registration.
A17: Excluded | B17: Approved indications, additional indications for marketed products, and AstraZeneca significant life-cycle-management tables.
A18: Deduplication | B18: The same lead asset is counted once at its highest disclosed phase; multiple indications and combinations are consolidated under the lead investigational asset.
A19: Normalization | B19: Company therapy areas were harmonized into eight cross-company categories. AstraZeneca oncology assets were classified as solid-tumor oncology or hematology based on disclosed areas under investigation.
A20: Interpretation | B20: A “shared” category means both companies have late-stage activity in the broad therapeutic area; it does not prove direct mechanism, indication or asset duplication.
A23: Important current-event caveat
A24: Reuters reported on Aug. 5, 2026 that a senior source said there were no ongoing discussions between the companies. The analysis is therefore framed as a portfolio thought experiment, not an announced transaction.
A27: Stacked-footprint + count-based lollipop update
A28: The chart restores the stacked late-stage program bars above each disease area. AstraZeneca and BMS use logo-inspired company colors; bubble size and number show distinct overlap count, while red tone shows analyst-coded directness. Portfolio balance remains excluded.
A29: Reproduction: the Plot_Data tab feeds the R and Python scripts; the Visual_Settings tab records the exact palette and visual encodings.

Sheet Asset_Data
A1: Company | B1: Source therapeutic area | C1: Normalized area | D1: Lead investigational asset / program | E1: Highest disclosed phase in snapshot | F1: Modality / mechanism | G1: Representative area(s) under investigation | H1: Source snapshot date | I1: Source URL | J1: Methodology notes | K1: Brand / marketed component | L1: Brand relationship | M1: Sales trend IDs
A2: AstraZeneca | B2: Oncology | C2: Solid-tumor oncology | D2: AZD9574 | E2: Phase II | F2: PARP1 inhibitor | G2: Advanced solid malignancies | H2: 2026-02-10 | I2: https://www.astrazeneca.com/content/dam/az/Investor_Relations/annual-report-2025/pdf/AstraZeneca_Development_Pipeline_2025.pdf
A3: AstraZeneca | B3: Oncology | C3: Solid-tumor oncology | D3: camizestrant | E3: Phase III / registration | F3: Next-generation oral SERD | G3: HR+/HER2- breast cancer, including advanced and adjuvant settings | H3: 2026-02-10 | I3: https://www.astrazeneca.com/content/dam/az/Investor_Relations/annual-report-2025/pdf/AstraZeneca_Development_Pipeline_2025.pdf | J3: Combination trials counted once under the lead investigational asset. | K3: Etcamah | L3: Approved brand for camizestrant (EU and Japan, 2026) | M3: ETCAMAH
A4: AstraZeneca | B4: Oncology | C4: Solid-tumor oncology | D4: FPI-2265 | E4: Phase II | F4: PSMA-targeted actinium radioconjugate | G4: Prostate cancer | H4: 2026-02-10 | I4: https://www.astrazeneca.com/content/dam/az/Investor_Relations/annual-report-2025/pdf/AstraZeneca_Development_Pipeline_2025.pdf
A5: AstraZeneca | B5: Oncology | C5: Solid-tumor oncology | D5: IPH5201 | E5: Phase II | F5: CD39 monoclonal antibody | G5: Neoadjuvant/adjuvant NSCLC; listed in combination with Imfinzi | H5: 2026-02-10 | I5: https://www.astrazeneca.com/content/dam/az/Investor_Relations/annual-report-2025/pdf/AstraZeneca_Development_Pipeline_2025.pdf | J5: Marketed combination backbone excluded from the asset count. | K5: Imfinzi | L5: Marketed combination backbone: Imfinzi (durvalumab) | M5: IMFINZI
A6: AstraZeneca | B6: Oncology | C6: Solid-tumor oncology | D6: puxitatug samrotecan | E6: Phase III | F6: B7-H4 TOP1i antibody-drug conjugate | G6: Solid tumors; Phase III endometrial cancer program | H6: 2026-02-10 | I6: https://www.astrazeneca.com/content/dam/az/Investor_Relations/annual-report-2025/pdf/AstraZeneca_Development_Pipeline_2025.pdf
A7: AstraZeneca | B7: Oncology | C7: Solid-tumor oncology | D7: rilvegostomig | E7: Phase III | F7: PD-1/TIGIT bispecific antibody | G7: NSCLC, HCC, gastric, biliary and other solid tumors | H7: 2026-02-10 | I7: https://www.astrazeneca.com/content/dam/az/Investor_Relations/annual-report-2025/pdf/AstraZeneca_Development_Pipeline_2025.pdf | J7: Multiple combinations and indications counted once under the lead asset.
A8: AstraZeneca | B8: Oncology | C8: Solid-tumor oncology | D8: saruparib | E8: Phase III | F8: PARP1 inhibitor | G8: Prostate and breast cancer programs | H8: 2026-02-10 | I8: https://www.astrazeneca.com/content/dam/az/Investor_Relations/annual-report-2025/pdf/AstraZeneca_Development_Pipeline_2025.pdf | J8: Multiple combinations and indications counted once under the lead asset.
A9: AstraZeneca | B9: Oncology | C9: Solid-tumor oncology | D9: sonesitatug vedotin | E9: Phase III | F9: CLDN18.2 MMAE antibody-drug conjugate | G9: Solid tumors; Phase III gastric cancer program | H9: 2026-02-10 | I9: https://www.astrazeneca.com/content/dam/az/Investor_Relations/annual-report-2025/pdf/AstraZeneca_Development_Pipeline_2025.pdf
A10: AstraZeneca | B10: Oncology | C10: Solid-tumor oncology | D10: tilatamig samrotecan | E10: Phase II | F10: EGFR/cMET TOP1i antibody-drug conjugate | G10: Solid tumors | H10: 2026-02-10 | I10: https://www.astrazeneca.com/content/dam/az/Investor_Relations/annual-report-2025/pdf/AstraZeneca_Development_Pipeline_2025.pdf
A11: AstraZeneca | B11: Oncology | C11: Solid-tumor oncology | D11: torvutatug samrotecan (AZD5335) | E11: Phase III | F11: FR-alpha TOP1i antibody-drug conjugate | G11: Ovarian cancer and other solid tumors | H11: 2026-02-10 | I11: https://www.astrazeneca.com/content/dam/az/Investor_Relations/annual-report-2025/pdf/AstraZeneca_Development_Pipeline_2025.pdf
A12: AstraZeneca | B12: Oncology | C12: Solid-tumor oncology | D12: volrustomig | E12: Phase III | F12: PD-1/CTLA-4 bispecific antibody | G12: NSCLC, cervical, head and neck, colorectal and mesothelioma | H12: 2026-02-10 | I12: https://www.astrazeneca.com/content/dam/az/Investor_Relations/annual-report-2025/pdf/AstraZeneca_Development_Pipeline_2025.pdf | J12: Multiple indications counted once under the lead asset.
A13: AstraZeneca | B13: Oncology | C13: Hematology | D13: AZD0120 | E13: Phase II | F13: CD19/BCMA CAR-T | G13: Multiple myeloma | H13: 2026-02-10 | I13: https://www.astrazeneca.com/content/dam/az/Investor_Relations/annual-report-2025/pdf/AstraZeneca_Development_Pipeline_2025.pdf
A14: AstraZeneca | B14: Oncology | C14: Hematology | D14: AZD0305 | E14: Phase II | F14: GPRC5D MMAE antibody-drug conjugate | G14: Relapsed/refractory multiple myeloma | H14: 2026-02-10 | I14: https://www.astrazeneca.com/content/dam/az/Investor_Relations/annual-report-2025/pdf/AstraZeneca_Development_Pipeline_2025.pdf
A15: AstraZeneca | B15: Oncology | C15: Hematology | D15: AZD3470 | E15: Phase II | F15: PRMT5 inhibitor | G15: Classical Hodgkin lymphoma; also early solid-tumor work | H15: 2026-02-10 | I15: https://www.astrazeneca.com/content/dam/az/Investor_Relations/annual-report-2025/pdf/AstraZeneca_Development_Pipeline_2025.pdf | J15: Classified to hematology based on the disclosed Phase II indication.
A16: AstraZeneca | B16: Oncology | C16: Hematology | D16: surovatamig | E16: Phase III | F16: CD19/CD3 T-cell engager | G16: B-cell malignancies including DLBCL, follicular lymphoma and B-ALL | H16: 2026-02-10 | I16: https://www.astrazeneca.com/content/dam/az/Investor_Relations/annual-report-2025/pdf/AstraZeneca_Development_Pipeline_2025.pdf | J16: Multiple indications counted once under the lead asset.
A17: AstraZeneca | B17: Respiratory & Immunology | C17: Immunology, respiratory & fibrosis | D17: atuliflapon | E17: Phase II | F17: FLAP inhibitor | G17: Asthma | H17: 2026-02-10 | I17: https://www.astrazeneca.com/content/dam/az/Investor_Relations/annual-report-2025/pdf/AstraZeneca_Development_Pipeline_2025.pdf
A18: AstraZeneca | B18: Respiratory & Immunology | C18: Immunology, respiratory & fibrosis | D18: AZD1163 | E18: Phase II | F18: PAD2/4 bispecific antibody | G18: Rheumatoid arthritis | H18: 2026-02-10 | I18: https://www.astrazeneca.com/content/dam/az/Investor_Relations/annual-report-2025/pdf/AstraZeneca_Development_Pipeline_2025.pdf
A19: AstraZeneca | B19: Respiratory & Immunology | C19: Immunology, respiratory & fibrosis | D19: AZD4604 | E19: Phase II | F19: Inhaled JAK1 inhibitor | G19: Asthma | H19: 2026-02-10 | I19: https://www.astrazeneca.com/content/dam/az/Investor_Relations/annual-report-2025/pdf/AstraZeneca_Development_Pipeline_2025.pdf
A20: AstraZeneca | B20: Respiratory & Immunology | C20: Immunology, respiratory & fibrosis | D20: AZD6793 | E20: Phase II | F20: IRAK4 inhibitor | G20: COPD | H20: 2026-02-10 | I20: https://www.astrazeneca.com/content/dam/az/Investor_Relations/annual-report-2025/pdf/AstraZeneca_Development_Pipeline_2025.pdf
A21: AstraZeneca | B21: Respiratory & Immunology | C21: Immunology, respiratory & fibrosis | D21: AZD7798 | E21: Phase II | F21: T-cell-subset-targeting monoclonal antibody | G21: Crohn's disease | H21: 2026-02-10 | I21: https://www.astrazeneca.com/content/dam/az/Investor_Relations/annual-report-2025/pdf/AstraZeneca_Development_Pipeline_2025.pdf
A22: AstraZeneca | B22: Respiratory & Immunology | C22: Immunology, respiratory & fibrosis | D22: AZD8630 | E22: Phase II | F22: Inhaled TSLP Fab | G22: Asthma | H22: 2026-02-10 | I22: https://www.astrazeneca.com/content/dam/az/Investor_Relations/annual-report-2025/pdf/AstraZeneca_Development_Pipeline_2025.pdf
A23: AstraZeneca | B23: Respiratory & Immunology | C23: Immunology, respiratory & fibrosis | D23: tozorakimab | E23: Phase III | F23: IL-33 monoclonal antibody | G23: COPD and severe viral lower respiratory tract disease | H23: 2026-02-10 | I23: https://www.astrazeneca.com/content/dam/az/Investor_Relations/annual-report-2025/pdf/AstraZeneca_Development_Pipeline_2025.pdf
A24: AstraZeneca | B24: CVRM | C24: Cardiovascular | D24: AZD5462 | E24: Phase II | F24: RXFP1 agonist | G24: Heart failure | H24: 2026-02-10 | I24: https://www.astrazeneca.com/content/dam/az/Investor_Relations/annual-report-2025/pdf/AstraZeneca_Development_Pipeline_2025.pdf
A25: AstraZeneca | B25: CVRM | C25: Cardiovascular | D25: baxdrostat | E25: Phase III / registration | F25: Aldosterone synthase inhibitor | G25: Hypertension and primary aldosteronism | H25: 2026-02-10 | I25: https://www.astrazeneca.com/content/dam/az/Investor_Relations/annual-report-2025/pdf/AstraZeneca_Development_Pipeline_2025.pdf | J25: Programs with dapagliflozin counted once under baxdrostat. | K25: Baxfendy | L25: Approved brand for baxdrostat (US, 2026) | M25: BAXFENDY
A26: AstraZeneca | B26: CVRM | C26: Cardiovascular | D26: laroprovstat | E26: Phase III | F26: PCSK9 inhibitor | G26: Dyslipidemia | H26: 2026-02-10 | I26: https://www.astrazeneca.com/content/dam/az/Investor_Relations/annual-report-2025/pdf/AstraZeneca_Development_Pipeline_2025.pdf
A27: AstraZeneca | B27: CVRM | C27: Renal & metabolic | D27: AZD2389 | E27: Phase II | F27: Anti-fibrotic mechanism | G27: Metabolic dysfunction-associated steatohepatitis | H27: 2026-02-10 | I27: https://www.astrazeneca.com/content/dam/az/Investor_Relations/annual-report-2025/pdf/AstraZeneca_Development_Pipeline_2025.pdf
A28: AstraZeneca | B28: CVRM | C28: Renal & metabolic | D28: AZD6234 | E28: Phase II | F28: Peptide therapy | G28: Chronic weight management | H28: 2026-02-10 | I28: https://www.astrazeneca.com/content/dam/az/Investor_Relations/annual-report-2025/pdf/AstraZeneca_Development_Pipeline_2025.pdf
A29: AstraZeneca | B29: CVRM | C29: Renal & metabolic | D29: AZD9550 + AZD6234 | E29: Phase II | F29: GLP-1/glucagon dual agonist plus amylin agonist | G29: Obesity | H29: 2026-02-10 | I29: https://www.astrazeneca.com/content/dam/az/Investor_Relations/annual-report-2025/pdf/AstraZeneca_Development_Pipeline_2025.pdf | J29: Two-investigational-asset combination counted as one disclosed program.
A30: AstraZeneca | B30: CVRM | C30: Renal & metabolic | D30: balcinrenone / dapagliflozin | E30: Phase III | F30: Mineralocorticoid receptor modulator plus SGLT2 inhibitor | G30: CKD and heart failure with CKD | H30: 2026-02-10 | I30: https://www.astrazeneca.com/content/dam/az/Investor_Relations/annual-report-2025/pdf/AstraZeneca_Development_Pipeline_2025.pdf | K30: Farxiga / Forxiga | L30: Marketed component: dapagliflozin | M30: FARXIGA
A31: AstraZeneca | B31: CVRM | C31: Renal & metabolic | D31: elecoglipron (AZD5004) | E31: Phase II | F31: Oral GLP-1 receptor agonist | G31: Type 2 diabetes and chronic weight management | H31: 2026-02-10 | I31: https://www.astrazeneca.com/content/dam/az/Investor_Relations/annual-report-2025/pdf/AstraZeneca_Development_Pipeline_2025.pdf
A32: AstraZeneca | B32: CVRM | C32: Renal & metabolic | D32: opemalirsen | E32: Phase II | F32: Podocyte-health therapeutic | G32: Nephropathy | H32: 2026-02-10 | I32: https://www.astrazeneca.com/content/dam/az/Investor_Relations/annual-report-2025/pdf/AstraZeneca_Development_Pipeline_2025.pdf
A33: AstraZeneca | B33: CVRM | C33: Renal & metabolic | D33: zibotentan / dapagliflozin | E33: Phase III | F33: Endothelin-A receptor antagonist plus SGLT2 inhibitor | G33: CKD with high proteinuria | H33: 2026-02-10 | I33: https://www.astrazeneca.com/content/dam/az/Investor_Relations/annual-report-2025/pdf/AstraZeneca_Development_Pipeline_2025.pdf | K33: Farxiga / Forxiga | L33: Marketed component: dapagliflozin | M33: FARXIGA
A34: AstraZeneca | B34: Rare Disease | C34: Rare disease | D34: ALXN1920 | E34: Phase II | F34: Kidney-targeted factor H fusion protein | G34: Primary membranous nephropathy | H34: 2026-02-10 | I34: https://www.astrazeneca.com/content/dam/az/Investor_Relations/annual-report-2025/pdf/AstraZeneca_Development_Pipeline_2025.pdf
A35: AstraZeneca | B35: Rare Disease | C35: Rare disease | D35: ALXN2030 | E35: Phase II | F35: Complement C3-targeting siRNA | G35: Antibody-mediated rejection | H35: 2026-02-10 | I35: https://www.astrazeneca.com/content/dam/az/Investor_Relations/annual-report-2025/pdf/AstraZeneca_Development_Pipeline_2025.pdf
A36: AstraZeneca | B36: Rare Disease | C36: Rare disease | D36: ALXN2420 | E36: Phase II | F36: Growth hormone receptor antagonist | G36: Acromegaly | H36: 2026-02-10 | I36: https://www.astrazeneca.com/content/dam/az/Investor_Relations/annual-report-2025/pdf/AstraZeneca_Development_Pipeline_2025.pdf
A37: AstraZeneca | B37: Rare Disease | C37: Rare disease | D37: tarperprumig | E37: Phase II | F37: Kinase inhibitor | G37: ANCA-associated vasculitis | H37: 2026-02-10 | I37: https://www.astrazeneca.com/content/dam/az/Investor_Relations/annual-report-2025/pdf/AstraZeneca_Development_Pipeline_2025.pdf
A38: AstraZeneca | B38: Rare Disease | C38: Rare disease | D38: anselamimab | E38: Phase III / registration | F38: Fibril-reactive monoclonal antibody | G38: AL amyloidosis | H38: 2026-02-10 | I38: https://www.astrazeneca.com/content/dam/az/Investor_Relations/annual-report-2025/pdf/AstraZeneca_Development_Pipeline_2025.pdf
A39: AstraZeneca | B39: Rare Disease | C39: Rare disease | D39: cliramitug | E39: Phase III | F39: Transthyretin depleter | G39: Transthyretin amyloid cardiomyopathy | H39: 2026-02-10 | I39: https://www.astrazeneca.com/content/dam/az/Investor_Relations/annual-report-2025/pdf/AstraZeneca_Development_Pipeline_2025.pdf
A40: AstraZeneca | B40: Rare Disease | C40: Rare disease | D40: efzimfotase alfa | E40: Phase III | F40: Next-generation TNSALP enzyme replacement therapy | G40: Hypophosphatasia | H40: 2026-02-10 | I40: https://www.astrazeneca.com/content/dam/az/Investor_Relations/annual-report-2025/pdf/AstraZeneca_Development_Pipeline_2025.pdf
...

Sheet Overlap_Units
A1: AZ + BMS overlap units - evidence behind bubble counts
A2: One row equals one distinct shared territory/class. Bubble counts are formula-driven from this table. Directness is an analyst-coded input: 1 limited, 2 moderate, 3 strong.
A4: Disease area | B4: Factor | C4: Overlap unit | D4: AZ evidence / programs | E4: BMS evidence / programs | F4: Directness (1-3) | G4: Rationale | H4: AZ source URL | I4: BMS source URL
A5: Solid-tumor oncology | B5: Shared indications | C5: NSCLC | D5: IPH5201; rilvegostomig; volrustomig | E5: pumitamig; iza-bren; navlimetostat; nivolumab + relatlimab HD | F5: 3 | G5: Multiple programs from both companies are being developed in NSCLC, creating direct disease-level overlap. | H5: https://www.astrazeneca.com/content/dam/az/Investor_Relations/annual-report-2025/pdf/AstraZeneca_Development_Pipeline_2025.pdf | I5: https://www.bms.com/assets/bms/us/en-us/pdf/investor-info/doc_presentations/2026/bms-pipeline-february-2026.pdf
A6: Solid-tumor oncology | B6: Shared indications | C6: Prostate cancer | D6: FPI-2265; saruparib | E6: AR ligand-directed degrader | F6: 3 | G6: Both companies have late-stage prostate-cancer programs, although targets and modalities differ. | H6: https://www.astrazeneca.com/content/dam/az/Investor_Relations/annual-report-2025/pdf/AstraZeneca_Development_Pipeline_2025.pdf | I6: https://www.bms.com/assets/bms/us/en-us/pdf/investor-info/doc_presentations/2026/bms-pipeline-february-2026.pdf
A7: Solid-tumor oncology | B7: Shared modalities | C7: Small-molecule targeted therapy | D7: AZD9574; camizestrant; saruparib | E7: navlimetostat; AR ligand-directed degrader | F7: 2 | G7: Both use oral/small-molecule targeted approaches in solid tumors. | H7: https://www.astrazeneca.com/content/dam/az/Investor_Relations/annual-report-2025/pdf/AstraZeneca_Development_Pipeline_2025.pdf | I7: https://www.bms.com/assets/bms/us/en-us/pdf/investor-info/doc_presentations/2026/bms-pipeline-february-2026.pdf
A8: Solid-tumor oncology | B8: Shared modalities | C8: Bispecific / dual-target biologics | D8: rilvegostomig; volrustomig | E8: pumitamig | F8: 3 | G8: Both have late-stage dual-target immuno-oncology biologics. | H8: https://www.astrazeneca.com/content/dam/az/Investor_Relations/annual-report-2025/pdf/AstraZeneca_Development_Pipeline_2025.pdf | I8: https://www.bms.com/assets/bms/us/en-us/pdf/investor-info/doc_presentations/2026/bms-pipeline-february-2026.pdf
A9: Solid-tumor oncology | B9: Shared modalities | C9: Antibody-drug conjugates | D9: puxitatug samrotecan; sonesitatug vedotin; tilatamig samrotecan; torvutatug samrotecan | E9: izalontamab brengitecan | F9: 3 | G9: Both have substantial ADC activity, with AstraZeneca contributing greater breadth. | H9: https://www.astrazeneca.com/content/dam/az/Investor_Relations/annual-report-2025/pdf/AstraZeneca_Development_Pipeline_2025.pdf | I9: https://www.bms.com/assets/bms/us/en-us/pdf/investor-info/doc_presentations/2026/bms-pipeline-february-2026.pdf
A10: Solid-tumor oncology | B10: Shared modalities | C10: Radiopharmaceuticals | D10: FPI-2265 | E10: RYZ101 | F10: 2 | G10: Both have targeted radiopharmaceutical programs, but in different tumor types and targets. | H10: https://www.astrazeneca.com/content/dam/az/Investor_Relations/annual-report-2025/pdf/AstraZeneca_Development_Pipeline_2025.pdf | I10: https://www.bms.com/assets/bms/us/en-us/pdf/investor-info/doc_presentations/2026/bms-pipeline-february-2026.pdf
A11: Solid-tumor oncology | B11: Shared target / mechanism | C11: PD-(L)1-based immuno-oncology | D11: rilvegostomig; volrustomig | E11: pumitamig; nivolumab + relatlimab HD; atigotatug + nivolumab | F11: 3 | G11: Both portfolios use PD-1/PD-L1-centered combinations or multispecific approaches. | H11: https://www.astrazeneca.com/content/dam/az/Investor_Relations/annual-report-2025/pdf/AstraZeneca_Development_Pipeline_2025.pdf | I11: https://www.bms.com/assets/bms/us/en-us/pdf/investor-info/doc_presentations/2026/bms-pipeline-february-2026.pdf
A12: Solid-tumor oncology | B12: Shared target / mechanism | C12: EGFR-directed therapeutics | D12: tilatamig samrotecan | E12: izalontamab brengitecan | F12: 2 | G12: Both have EGFR-directed ADC programs, paired with different second targets. | H12: https://www.astrazeneca.com/content/dam/az/Investor_Relations/annual-report-2025/pdf/AstraZeneca_Development_Pipeline_2025.pdf | I12: https://www.bms.com/assets/bms/us/en-us/pdf/investor-info/doc_presentations/2026/bms-pipeline-february-2026.pdf
A13: Solid-tumor oncology | B13: Stage alignment | C13: Phase II | D13: AZD9574; FPI-2265; IPH5201; tilatamig samrotecan | E13: iza-bren; navlimetostat | F13: 2 | G13: Both companies have Phase II programs in the disease area. | H13: https://www.astrazeneca.com/content/dam/az/Investor_Relations/annual-report-2025/pdf/AstraZeneca_Development_Pipeline_2025.pdf | I13: https://www.bms.com/assets/bms/us/en-us/pdf/investor-info/doc_presentations/2026/bms-pipeline-february-2026.pdf
A14: Solid-tumor oncology | B14: Stage alignment | C14: Phase III / registration | D14: camizestrant; puxitatug samrotecan; rilvegostomig; saruparib; sonesitatug vedotin; torvutatug samrotecan; volrustomig | E14: pumitamig; AR ligand-directed degrader; atigotatug + nivolumab; nivolumab + relatlimab HD; RYZ101 | F14: 3 | G14: Both have broad Phase III/registration portfolios in solid tumors. | H14: https://www.astrazeneca.com/content/dam/az/Investor_Relations/annual-report-2025/pdf/AstraZeneca_Development_Pipeline_2025.pdf | I14: https://www.bms.com/assets/bms/us/en-us/pdf/investor-info/doc_presentations/2026/bms-pipeline-february-2026.pdf
A15: Hematology | B15: Shared indications | C15: Multiple myeloma | D15: AZD0120; AZD0305 | E15: arlo-cel; iberdomide; mezigdomide | F15: 3 | G15: Both companies have multiple late-stage programs in multiple myeloma. | H15: https://www.astrazeneca.com/content/dam/az/Investor_Relations/annual-report-2025/pdf/AstraZeneca_Development_Pipeline_2025.pdf | I15: https://www.bms.com/assets/bms/us/en-us/pdf/investor-info/doc_presentations/2026/bms-pipeline-february-2026.pdf
A16: Hematology | B16: Shared indications | C16: B-cell lymphoma | D16: surovatamig | E16: golcadomide | F16: 3 | G16: Both have Phase III programs in B-cell lymphoma territories. | H16: https://www.astrazeneca.com/content/dam/az/Investor_Relations/annual-report-2025/pdf/AstraZeneca_Development_Pipeline_2025.pdf | I16: https://www.bms.com/assets/bms/us/en-us/pdf/investor-info/doc_presentations/2026/bms-pipeline-february-2026.pdf
... A27: Cardiovascular | B27: Stage alignment | C27: Phase III / registration | D27: baxdrostat; laroprovstat | E27: milvexian | F27: 1 | G27: Both have Phase III programs, but in different cardiovascular indications. | H27: https://www.astrazeneca.com/content/dam/az/Investor_Relations/annual-report-2025/pdf/AstraZeneca_Development_Pipeline_2025.pdf | I27: https://www.bms.com/assets/bms/us/en-us/pdf/investor-info/doc_presentations/2026/bms-pipeline-february-2026.pdf

Sheet Overlap_Matrix
A1: AstraZeneca + BMS: count-based portfolio collision matrix
A2: Counts represent distinct shared territories/classes and are calculated from Overlap_Units. Intensity is the maximum directness score among the units in each cell. Portfolio balance has been removed.
A4: Disease area | B4: Plot label | C4: AZ programs | D4: BMS programs | E4: Combined programs | F4: Shared indications | G4: Indication intensity | H4: Shared modalities | I4: Modality intensity | J4: Shared target / mechanism | K4: Target intensity | L4: Stage alignment | M4: Stage intensity | N4: Strategic read
A5: Solid-tumor oncology | B5: Solid tumors | C5: =COUNTIFS(Asset_Data!$A:$A,"AstraZeneca",Asset_Data!$C:$C,$A5) | D5: =COUNTIFS(Asset_Data!$A:$A,"Bristol Myers Squibb",Asset_Data!$C:$C,$A5) | E5: =SUM(C5:D5) | F5: =COUNTIFS(Overlap_Units!$A:$A,$A5,Overlap_Units!$B:$B,F4) | G5: =IF(F5=0,0,MAXIFS(Overlap_Units!$F:$F,Overlap_Units!$A:$A,$A5,Overlap_Units!$B:$B,F4)) | H5: =COUNTIFS(Overlap_Units!$A:$A,$A5,Overlap_Units!$B:$B,H4) | I5: =IF(H5=0,0,MAXIFS(Overlap_Units!$F:$F,Overlap_Units!$A:$A,$A5,Overlap_Units!$B:$B,H4)) | J5: =COUNTIFS(Overlap_Units!$A:$A,$A5,Overlap_Units!$B:$B,J4) | K5: =IF(J5=0,0,MAXIFS(Overlap_Units!$F:$F,Overlap_Units!$A:$A,$A5,Overlap_Units!$B:$B,J4)) | L5: =COUNTIFS(Overlap_Units!$A:$A,$A5,Overlap_Units!$B:$B,L4) | M5: =IF(L5=0,0,MAXIFS(Overlap_Units!$F:$F,Overlap_Units!$A:$A,$A5,Overlap_Units!$B:$B,L4)) | N5: Strong collision
A6: Hematology | B6: Hematology | C6: =COUNTIFS(Asset_Data!$A:$A,"AstraZeneca",Asset_Data!$C:$C,$A6) | D6: =COUNTIFS(Asset_Data!$A:$A,"Bristol Myers Squibb",Asset_Data!$C:$C,$A6) | E6: =SUM(C6:D6) | F6: =COUNTIFS(Overlap_Units!$A:$A,$A6,Overlap_Units!$B:$B,F4) | G6: =IF(F6=0,0,MAXIFS(Overlap_Units!$F:$F,Overlap_Units!$A:$A,$A6,Overlap_Units!$B:$B,F4)) | H6: =COUNTIFS(Overlap_Units!$A:$A,$A6,Overlap_Units!$B:$B,H4) | I6: =IF(H6=0,0,MAXIFS(Overlap_Units!$F:$F,Overlap_Units!$A:$A,$A6,Overlap_Units!$B:$B,H4)) | J6: =COUNTIFS(Overlap_Units!$A:$A,$A6,Overlap_Units!$B:$B,J4) | K6: =IF(J6=0,0,MAXIFS(Overlap_Units!$F:$F,Overlap_Units!$A:$A,$A6,Overlap_Units!$B:$B,J4)) | L6: =COUNTIFS(Overlap_Units!$A:$A,$A6,Overlap_Units!$B:$B,L4) | M6: =IF(L6=0,0,MAXIFS(Overlap_Units!$F:$F,Overlap_Units!$A:$A,$A6,Overlap_Units!$B:$B,L4)) | N6: Strong collision
A7: Immunology, respiratory & fibrosis | B7: Immunology / resp. / fibrosis | C7: =COUNTIFS(Asset_Data!$A:$A,"AstraZeneca",Asset_Data!$C:$C,$A7) | D7: =COUNTIFS(Asset_Data!$A:$A,"Bristol Myers Squibb",Asset_Data!$C:$C,$A7) | E7: =SUM(C7:D7) | F7: =COUNTIFS(Overlap_Units!$A:$A,$A7,Overlap_Units!$B:$B,F4) | G7: =IF(F7=0,0,MAXIFS(Overlap_Units!$F:$F,Overlap_Units!$A:$A,$A7,Overlap_Units!$B:$B,F4)) | H7: =COUNTIFS(Overlap_Units!$A:$A,$A7,Overlap_Units!$B:$B,H4) | I7: =IF(H7=0,0,MAXIFS(Overlap_Units!$F:$F,Overlap_Units!$A:$A,$A7,Overlap_Units!$B:$B,H4)) | J7: =COUNTIFS(Overlap_Units!$A:$A,$A7,Overlap_Units!$B:$B,J4) | K7: =IF(J7=0,0,MAXIFS(Overlap_Units!$F:$F,Overlap_Units!$A:$A,$A7,Overlap_Units!$B:$B,J4)) | L7: =COUNTIFS(Overlap_Units!$A:$A,$A7,Overlap_Units!$B:$B,L4) | M7: =IF(L7=0,0,MAXIFS(Overlap_Units!$F:$F,Overlap_Units!$A:$A,$A7,Overlap_Units!$B:$B,L4)) | N7: Platform adjacency
A8: Cardiovascular | B8: CV | C8: =COUNTIFS(Asset_Data!$A:$A,"AstraZeneca",Asset_Data!$C:$C,$A8) | D8: =COUNTIFS(Asset_Data!$A:$A,"Bristol Myers Squibb",Asset_Data!$C:$C,$A8) | E8: =SUM(C8:D8) | F8: =COUNTIFS(Overlap_Units!$A:$A,$A8,Overlap_Units!$B:$B,F4) | G8: =IF(F8=0,0,MAXIFS(Overlap_Units!$F:$F,Overlap_Units!$A:$A,$A8,Overlap_Units!$B:$B,F4)) | H8: =COUNTIFS(Overlap_Units!$A:$A,$A8,Overlap_Units!$B:$B,H4) | I8: =IF(H8=0,0,MAXIFS(Overlap_Units!$F:$F,Overlap_Units!$A:$A,$A8,Overlap_Units!$B:$B,H4)) | J8: =COUNTIFS(Overlap_Units!$A:$A,$A8,Overlap_Units!$B:$B,J4) | K8: =IF(J8=0,0,MAXIFS(Overlap_Units!$F:$F,Overlap_Units!$A:$A,$A8,Overlap_Units!$B:$B,J4)) | L8: =COUNTIFS(Overlap_Units!$A:$A,$A8,Overlap_Units!$B:$B,L4) | M8: =IF(L8=0,0,MAXIFS(Overlap_Units!$F:$F,Overlap_Units!$A:$A,$A8,Overlap_Units!$B:$B,L4)) | N8: Narrow adjacency
A9: Rare disease | B9: Rare disease | C9: =COUNTIFS(Asset_Data!$A:$A,"AstraZeneca",Asset_Data!$C:$C,$A9) | D9: =COUNTIFS(Asset_Data!$A:$A,"Bristol Myers Squibb",Asset_Data!$C:$C,$A9) | E9: =SUM(C9:D9) | F9: =COUNTIFS(Overlap_Units!$A:$A,$A9,Overlap_Units!$B:$B,F4) | G9: =IF(F9=0,0,MAXIFS(Overlap_Units!$F:$F,Overlap_Units!$A:$A,$A9,Overlap_Units!$B:$B,F4)) | H9: =COUNTIFS(Overlap_Units!$A:$A,$A9,Overlap_Units!$B:$B,H4) | I9: =IF(H9=0,0,MAXIFS(Overlap_Units!$F:$F,Overlap_Units!$A:$A,$A9,Overlap_Units!$B:$B,H4)) | J9: =COUNTIFS(Overlap_Units!$A:$A,$A9,Overlap_Units!$B:$B,J4) | K9: =IF(J9=0,0,MAXIFS(Overlap_Units!$F:$F,Overlap_Units!$A:$A,$A9,Overlap_Units!$B:$B,J4)) | L9: =COUNTIFS(Overlap_Units!$A:$A,$A9,Overlap_Units!$B:$B,L4) | M9: =IF(L9=0,0,MAXIFS(Overlap_Units!$F:$F,Overlap_Units!$A:$A,$A9,Overlap_Units!$B:$B,L4)) | N9: AZ-led fit
A10: Renal & metabolic | B10: Renal / metabolic | C10: =COUNTIFS(Asset_Data!$A:$A,"AstraZeneca",Asset_Data!$C:$C,$A10) | D10: =COUNTIFS(Asset_Data!$A:$A,"Bristol Myers Squibb",Asset_Data!$C:$C,$A10) | E10: =SUM(C10:D10) | F10: =COUNTIFS(Overlap_Units!$A:$A,$A10,Overlap_Units!$B:$B,F4) | G10: =IF(F10=0,0,MAXIFS(Overlap_Units!$F:$F,Overlap_Units!$A:$A,$A10,Overlap_Units!$B:$B,F4)) | H10: =COUNTIFS(Overlap_Units!$A:$A,$A10,Overlap_Units!$B:$B,H4) | I10: =IF(H10=0,0,MAXIFS(Overlap_Units!$F:$F,Overlap_Units!$A:$A,$A10,Overlap_Units!$B:$B,H4)) | J10: =COUNTIFS(Overlap_Units!$A:$A,$A10,Overlap_Units!$B:$B,J4) | K10: =IF(J10=0,0,MAXIFS(Overlap_Units!$F:$F,Overlap_Units!$A:$A,$A10,Overlap_Units!$B:$B,J4)) | L10: =COUNTIFS(Overlap_Units!$A:$A,$A10,Overlap_Units!$B:$B,L4) | M10: =IF(L10=0,0,MAXIFS(Overlap_Units!$F:$F,Overlap_Units!$A:$A,$A10,Overlap_Units!$B:$B,L4)) | N10: AZ-led fit
A11: Infectious disease | B11: Infectious disease | C11: =COUNTIFS(Asset_Data!$A:$A,"AstraZeneca",Asset_Data!$C:$C,$A11) | D11: =COUNTIFS(Asset_Data!$A:$A,"Bristol Myers Squibb",Asset_Data!$C:$C,$A11) | E11: =SUM(C11:D11) | F11: =COUNTIFS(Overlap_Units!$A:$A,$A11,Overlap_Units!$B:$B,F4) | G11: =IF(F11=0,0,MAXIFS(Overlap_Units!$F:$F,Overlap_Units!$A:$A,$A11,Overlap_Units!$B:$B,F4)) | H11: =COUNTIFS(Overlap_Units!$A:$A,$A11,Overlap_Units!$B:$B,H4) | I11: =IF(H11=0,0,MAXIFS(Overlap_Units!$F:$F,Overlap_Units!$A:$A,$A11,Overlap_Units!$B:$B,H4)) | J11: =COUNTIFS(Overlap_Units!$A:$A,$A11,Overlap_Units!$B:$B,J4) | K11: =IF(J11=0,0,MAXIFS(Overlap_Units!$F:$F,Overlap_Units!$A:$A,$A11,Overlap_Units!$B:$B,J4)) | L11: =COUNTIFS(Overlap_Units!$A:$A,$A11,Overlap_Units!$B:$B,L4) | M11: =IF(L11=0,0,MAXIFS(Overlap_Units!$F:$F,Overlap_Units!$A:$A,$A11,Overlap_Units!$B:$B,L4)) | N11: AZ-led fit
A12: Neuroscience | B12: Neuroscience | C12: =COUNTIFS(Asset_Data!$A:$A,"AstraZeneca",Asset_Data!$C:$C,$A12) | D12: =COUNTIFS(Asset_Data!$A:$A,"Bristol Myers Squibb",Asset_Data!$C:$C,$A12) | E12: =SUM(C12:D12) | F12: =COUNTIFS(Overlap_Units!$A:$A,$A12,Overlap_Units!$B:$B,F4) | G12: =IF(F12=0,0,MAXIFS(Overlap_Units!$F:$F,Overlap_Units!$A:$A,$A12,Overlap_Units!$B:$B,F4)) | H12: =COUNTIFS(Overlap_Units!$A:$A,$A12,Overlap_Units!$B:$B,H4) | I12: =IF(H12=0,0,MAXIFS(Overlap_Units!$F:$F,Overlap_Units!$A:$A,$A12,Overlap_Units!$B:$B,H4)) | J12: =COUNTIFS(Overlap_Units!$A:$A,$A12,Overlap_Units!$B:$B,J4) | K12: =IF(J12=0,0,MAXIFS(Overlap_Units!$F:$F,Overlap_Units!$A:$A,$A12,Overlap_Units!$B:$B,J4)) | L12: =COUNTIFS(Overlap_Units!$A:$A,$A12,Overlap_Units!$B:$B,L4) | M12: =IF(L12=0,0,MAXIFS(Overlap_Units!$F:$F,Overlap_Units!$A:$A,$A12,Overlap_Units!$B:$B,L4)) | N12: BMS-led fit
A15: Definition: overlap count = number of distinct shared territories/classes, not the number of all possible AZ-BMS asset pairs. Late-stage program = unique lead asset in Phase II or Phase III/pivotal/registration.

Sheet Plot_Data
A1: Disease area | B1: Plot label | C1: Factor | D1: Overlap count | E1: Intensity | F1: AZ programs | G1: BMS programs | H1: Relationship
A2: =Overlap_Matrix!A5 | B2: =Overlap_Matrix!B5 | C2: Shared indications | D2: =Overlap_Matrix!F5 | E2: =Overlap_Matrix!G5 | F2: =Overlap_Matrix!C5 | G2: =Overlap_Matrix!D5 | H2: =Overlap_Matrix!N5
A3: =Overlap_Matrix!A5 | B3: =Overlap_Matrix!B5 | C3: Shared modalities | D3: =Overlap_Matrix!H5 | E3: =Overlap_Matrix!I5 | F3: =Overlap_Matrix!C5 | G3: =Overlap_Matrix!D5 | H3: =Overlap_Matrix!N5
A4: =Overlap_Matrix!A5 | B4: =Overlap_Matrix!B5 | C4: Shared target / mechanism | D4: =Overlap_Matrix!J5 | E4: =Overlap_Matrix!K5 | F4: =Overlap_Matrix!C5 | G4: =Overlap_Matrix!D5 | H4: =Overlap_Matrix!N5
A5: =Overlap_Matrix!A5 | B5: =Overlap_Matrix!B5 | C5: Stage alignment | D5: =Overlap_Matrix!L5 | E5: =Overlap_Matrix!M5 | F5: =Overlap_Matrix!C5 | G5: =Overlap_Matrix!D5 | H5: =Overlap_Matrix!N5
A6: =Overlap_Matrix!A6 | B6: =Overlap_Matrix!B6 | C6: Shared indications | D6: =Overlap_Matrix!F6 | E6: =Overlap_Matrix!G6 | F6: =Overlap_Matrix!C6 | G6: =Overlap_Matrix!D6 | H6: =Overlap_Matrix!N6
A7: =Overlap_Matrix!A6 | B7: =Overlap_Matrix!B6 | C7: Shared modalities | D7: =Overlap_Matrix!H6 | E7: =Overlap_Matrix!I6 | F7: =Overlap_Matrix!C6 | G7: =Overlap_Matrix!D6 | H7: =Overlap_Matrix!N6
A8: =Overlap_Matrix!A6 | B8: =Overlap_Matrix!B6 | C8: Shared target / mechanism | D8: =Overlap_Matrix!J6 | E8: =Overlap_Matrix!K6 | F8: =Overlap_Matrix!C6 | G8: =Overlap_Matrix!D6 | H8: =Overlap_Matrix!N6
A9: =Overlap_Matrix!A6 | B9: =Overlap_Matrix!B6 | C9: Stage alignment | D9: =Overlap_Matrix!L6 | E9: =Overlap_Matrix!M6 | F9: =Overlap_Matrix!C6 | G9: =Overlap_Matrix!D6 | H9: =Overlap_Matrix!N6
A10: =Overlap_Matrix!A7 | B10: =Overlap_Matrix!B7 | C10: Shared indications | D10: =Overlap_Matrix!F7 | E10: =Overlap_Matrix!G7 | F10: =Overlap_Matrix!C7 | G10: =Overlap_Matrix!D7 | H10: =Overlap_Matrix!N7
A11: =Overlap_Matrix!A7 | B11: =Overlap_Matrix!B7 | C11: Shared modalities | D11: =Overlap_Matrix!H7 | E11: =Overlap_Matrix!I7 | F11: =Overlap_Matrix!C7 | G11: =Overlap_Matrix!D7 | H11: =Overlap_Matrix!N7
A12: =Overlap_Matrix!A7 | B12: =Overlap_Matrix!B7 | C12: Shared target / mechanism | D12: =Overlap_Matrix!J7 | E12: =Overlap_Matrix!K7 | F12: =Overlap_Matrix!C7 | G12: =Overlap_Matrix!D7 | H12: =Overlap_Matrix!N7
A13: =Overlap_Matrix!A7 | B13: =Overlap_Matrix!B7 | C13: Stage alignment | D13: =Overlap_Matrix!L7 | E13: =Overlap_Matrix!M7 | F13: =Overlap_Matrix!C7 | G13: =Overlap_Matrix!D7 | H13: =Overlap_Matrix!N7
A14: =Overlap_Matrix!A8 | B14: =Overlap_Matrix!B8 | C14: Shared indications | D14: =Overlap_Matrix!F8 | E14: =Overlap_Matrix!G8 | F14: =Overlap_Matrix!C8 | G14: =Overlap_Matrix!D8 | H14: =Overlap_Matrix!N8
A15: =Overlap_Matrix!A8 | B15: =Overlap_Matrix!B8 | C15: Shared modalities | D15: =Overlap_Matrix!H8 | E15: =Overlap_Matrix!I8 | F15: =Overlap_Matrix!C8 | G15: =Overlap_Matrix!D8 | H15: =Overlap_Matrix!N8
A16: =Overlap_Matrix!A8 | B16: =Overlap_Matrix!B8 | C16: Shared target / mechanism | D16: =Overlap_Matrix!J8 | E16: =Overlap_Matrix!K8 | F16: =Overlap_Matrix!C8 | G16: =Overlap_Matrix!D8 | H16: =Overlap_Matrix!N8
A17: =Overlap_Matrix!A8 | B17: =Overlap_Matrix!B8 | C17: Stage alignment | D17: =Overlap_Matrix!L8 | E17: =Overlap_Matrix!M8 | F17: =Overlap_Matrix!C8 | G17: =Overlap_Matrix!D8 | H17: =Overlap_Matrix!N8
A18: =Overlap_Matrix!A9 | B18: =Overlap_Matrix!B9 | C18: Shared indications | D18: =Overlap_Matrix!F9 | E18: =Overlap_Matrix!G9 | F18: =Overlap_Matrix!C9 | G18: =Overlap_Matrix!D9 | H18: =Overlap_Matrix!N9
A19: =Overlap_Matrix!A9 | B19: =Overlap_Matrix!B9 | C19: Shared modalities | D19: =Overlap_Matrix!H9 | E19: =Overlap_Matrix!I9 | F19: =Overlap_Matrix!C9 | G19: =Overlap_Matrix!D9 | H19: =Overlap_Matrix!N9
A20: =Overlap_Matrix!A9 | B20: =Overlap_Matrix!B9 | C20: Shared target / mechanism | D20: =Overlap_Matrix!J9 | E20: =Overlap_Matrix!K9 | F20: =Overlap_Matrix!C9 | G20: =Overlap_Matrix!D9 | H20: =Overlap_Matrix!N9
A21: =Overlap_Matrix!A9 | B21: =Overlap_Matrix!B9 | C21: Stage alignment | D21: =Overlap_Matrix!L9 | E21: =Overlap_Matrix!M9 | F21: =Overlap_Matrix!C9 | G21: =Overlap_Matrix!D9 | H21: =Overlap_Matrix!N9
A22: =Overlap_Matrix!A10 | B22: =Overlap_Matrix!B10 | C22: Shared indications | D22: =Overlap_Matrix!F10 | E22: =Overlap_Matrix!G10 | F22: =Overlap_Matrix!C10 | G22: =Overlap_Matrix!D10 | H22: =Overlap_Matrix!N10
A23: =Overlap_Matrix!A10 | B23: =Overlap_Matrix!B10 | C23: Shared modalities | D23: =Overlap_Matrix!H10 | E23: =Overlap_Matrix!I10 | F23: =Overlap_Matrix!C10 | G23: =Overlap_Matrix!D10 | H23: =Overlap_Matrix!N10
A24: =Overlap_Matrix!A10 | B24: =Overlap_Matrix!B10 | C24: Shared target / mechanism | D24: =Overlap_Matrix!J10 | E24: =Overlap_Matrix!K10 | F24: =Overlap_Matrix!C10 | G24: =Overlap_Matrix!D10 | H24: =Overlap_Matrix!N10
A25: =Overlap_Matrix!A10 | B25: =Overlap_Matrix!B10 | C25: Stage alignment | D25: =Overlap_Matrix!L10 | E25: =Overlap_Matrix!M10 | F25: =Overlap_Matrix!C10 | G25: =Overlap_Matrix!D10 | H25: =Overlap_Matrix!N10
A26: =Overlap_Matrix!A11 | B26: =Overlap_Matrix!B11 | C26: Shared indications | D26: =Overlap_Matrix!F11 | E26: =Overlap_Matrix!G11 | F26: =Overlap_Matrix!C11 | G26: =Overlap_Matrix!D11 | H26: =Overlap_Matrix!N11
A27: =Overlap_Matrix!A11 | B27: =Overlap_Matrix!B11 | C27: Shared modalities | D27: =Overlap_Matrix!H11 | E27: =Overlap_Matrix!I11 | F27: =Overlap_Matrix!C11 | G27: =Overlap_Matrix!D11 | H27: =Overlap_Matrix!N11
A28: =Overlap_Matrix!A11 | B28: =Overlap_Matrix!B11 | C28: Shared target / mechanism | D28: =Overlap_Matrix!J11 | E28: =Overlap_Matrix!K11 | F28: =Overlap_Matrix!C11 | G28: =Overlap_Matrix!D11 | H28: =Overlap_Matrix!N11
A29: =Overlap_Matrix!A11 | B29: =Overlap_Matrix!B11 | C29: Stage alignment | D29: =Overlap_Matrix!L11 | E29: =Overlap_Matrix!M11 | F29: =Overlap_Matrix!C11 | G29: =Overlap_Matrix!D11 | H29: =Overlap_Matrix!N11
A30: =Overlap_Matrix!A12 | B30: =Overlap_Matrix!B12 | C30: Shared indications | D30: =Overlap_Matrix!F12 | E30: =Overlap_Matrix!G12 | F30: =Overlap_Matrix!C12 | G30: =Overlap_Matrix!D12 | H30: =Overlap_Matrix!N12
A31: =Overlap_Matrix!A12 | B31: =Overlap_Matrix!B12 | C31: Shared modalities | D31: =Overlap_Matrix!H12 | E31: =Overlap_Matrix!I12 | F31: =Overlap_Matrix!C12 | G31: =Overlap_Matrix!D12 | H31: =Overlap_Matrix!N12
A32: =Overlap_Matrix!A12 | B32: =Overlap_Matrix!B12 | C32: Shared target / mechanism | D32: =Overlap_Matrix!J12 | E32: =Overlap_Matrix!K12 | F32: =Overlap_Matrix!C12 | G32: =Overlap_Matrix!D12 | H32: =Overlap_Matrix!N12
A33: =Overlap_Matrix!A12 | B33: =Overlap_Matrix!B12 | C33: Stage alignment | D33: =Overlap_Matrix!L12 | E33: =Overlap_Matrix!M12 | F33: =Overlap_Matrix!C12 | G33: =Overlap_Matrix!D12 | H33: =Overlap_Matrix!N12

Sheet Visual_Settings
A1: Visual settings and encoding
A3: Element | B3: Hex | C3: Use | D3: Notes
A4: AstraZeneca primary | B4: #7A1F63 | C4: Stacked bar | D4: Logo-inspired plum
A5: AstraZeneca accent | B5: #D7A900 | C5: Thin bar/legend accent | D5: Logo-inspired gold
A6: BMS primary | B6: #263B73 | C6: Stacked bar | D6: Logo-inspired navy
A7: BMS accent | B7: #76519A | C7: Thin bar/legend accent | D7: Hand-mark-inspired violet
A8: Overlap - limited | B8: #F7D3D0 | C8: Bubble fill | D8: Low directness
A9: Overlap - moderate | B9: #ED756D | C9: Bubble fill | D9: Medium directness
A10: Overlap - strong | B10: #C51F36 | C10: Bubble fill | D10: High directness
A11: Bubble outline | B11: #8E1829 | C11: Bubble border | D11: Consistent red boundary
A12: Page background | B12: #F4F1EC | C12: Canvas | D12: Warm neutral
A13: Card background | B13: #FFFFFF | C13: Main panel | D13: White
A14: Primary text | B14: #182230 | C14: Text | D14: Dark ink
A17: Encoding definitions
A18: Stacked-bar height | B18: Number of unique late-stage programs by company and disease area
A19: Bubble label + size | B19: Number of distinct shared overlap units in the corresponding disease area and portfolio dimension
A20: Bubble red tone | B20: Analyst-coded directness: 1 limited, 2 moderate, 3 strong
A21: Hollow circle | B21: No identified overlap unit under the current normalization

Sheet Summary
A1: Portfolio summary (formula-driven)
A3: Normalized area | B3: AstraZeneca | C3: Bristol Myers Squibb | D3: Combined | E3: Portfolio relationship
A4: Solid-tumor oncology | B4: =COUNTIFS(Asset_Data!$A:$A,"AstraZeneca",Asset_Data!$C:$C,$A4) | C4: =COUNTIFS(Asset_Data!$A:$A,"Bristol Myers Squibb",Asset_Data!$C:$C,$A4) | D4: =SUM(B4:C4) | E4: =IF(AND(B4>0,C4>0),"Shared territory","One-sided strength")
A5: Immunology, respiratory & fibrosis | B5: =COUNTIFS(Asset_Data!$A:$A,"AstraZeneca",Asset_Data!$C:$C,$A5) | C5: =COUNTIFS(Asset_Data!$A:$A,"Bristol Myers Squibb",Asset_Data!$C:$C,$A5) | D5: =SUM(B5:C5) | E5: =IF(AND(B5>0,C5>0),"Shared territory","One-sided strength")
A6: Hematology | B6: =COUNTIFS(Asset_Data!$A:$A,"AstraZeneca",Asset_Data!$C:$C,$A6) | C6: =COUNTIFS(Asset_Data!$A:$A,"Bristol Myers Squibb",Asset_Data!$C:$C,$A6) | D6: =SUM(B6:C6) | E6: =IF(AND(B6>0,C6>0),"Shared territory","One-sided strength")
A7: Cardiovascular | B7: =COUNTIFS(Asset_Data!$A:$A,"AstraZeneca",Asset_Data!$C:$C,$A7) | C7: =COUNTIFS(Asset_Data!$A:$A,"Bristol Myers Squibb",Asset_Data!$C:$C,$A7) | D7: =SUM(B7:C7) | E7: =IF(AND(B7>0,C7>0),"Shared territory","One-sided strength")
A8: Rare disease | B8: =COUNTIFS(Asset_Data!$A:$A,"AstraZeneca",Asset_Data!$C:$C,$A8) | C8: =COUNTIFS(Asset_Data!$A:$A,"Bristol Myers Squibb",Asset_Data!$C:$C,$A8) | D8: =SUM(B8:C8) | E8: =IF(AND(B8>0,C8>0),"Shared territory","One-sided strength")
A9: Renal & metabolic | B9: =COUNTIFS(Asset_Data!$A:$A,"AstraZeneca",Asset_Data!$C:$C,$A9) | C9: =COUNTIFS(Asset_Data!$A:$A,"Bristol Myers Squibb",Asset_Data!$C:$C,$A9) | D9: =SUM(B9:C9) | E9: =IF(AND(B9>0,C9>0),"Shared territory","One-sided strength")
A10: Infectious disease | B10: =COUNTIFS(Asset_Data!$A:$A,"AstraZeneca",Asset_Data!$C:$C,$A10) | C10: =COUNTIFS(Asset_Data!$A:$A,"Bristol Myers Squibb",Asset_Data!$C:$C,$A10) | D10: =SUM(B10:C10) | E10: =IF(AND(B10>0,C10>0),"Shared territory","One-sided strength")
A11: Neuroscience | B11: =COUNTIFS(Asset_Data!$A:$A,"AstraZeneca",Asset_Data!$C:$C,$A11) | C11: =COUNTIFS(Asset_Data!$A:$A,"Bristol Myers Squibb",Asset_Data!$C:$C,$A11) | D11: =SUM(B11:C11) | E11: =IF(AND(B11>0,C11>0),"Shared territory","One-sided strength")
A12: Total | B12: =SUM(B4:B11) | C12: =SUM(C4:C11) | D12: =SUM(D4:D11)

Sheet LinkedIn_Draft
A1: LinkedIn post draft
A3: The AstraZeneca–BMS rumor appears to be off the table. But the portfolio thought experiment is still interesting. I mapped the companies’ Phase II/III investigational portfolios using matched February 2026 company disclosures. The result looks less like a simple “R&D machine” and more like a mix of portfolio fit and collision. The collision zone is oncology. Across the mapped portfolio, the two companies have 18 solid-tumor programs and 8 hematology programs. Both are active in immuno-oncology and lung cancer, while the broader pipelines span ADCs, bispecifics, radiopharmaceuticals, cell therapy and targeted protein degradation. The complementarity is mostly outside oncology. AstraZeneca contributes much more breadth in rare disease, renal/metabolic disease and infectious disease. BMS adds a distinct neuroscience position, while both companies also overlap in immunology/respiratory/fibrosis and cardiovascular disease. The real integration question would not be whether the combined company had enough assets. It would be which programs, platforms, teams and partnerships would survive portfolio prioritization. More breadth creates more optionality—but also more duplication and harder choices. My takeaway: the strategic value would depend less on adding the two pipelines together, and more on how aggressively management rationalized the overlap without disrupting the science that created it. What would you scrutinize first: portfolio overlap, patent cliffs or integration risk? Data note: unique lead investigational assets/programs in Phase II or III/pivotal/registration; matched AstraZeneca (Feb. 10, 2026) and BMS (Feb. 5, 2026) disclosures; approved-indication expansions and significant life-cycle-management programs excluded.
A5: Optional shorter opening
A6: The rumor may be dead. The portfolio question is not: would AstraZeneca + BMS create strategic fit—or force a wave of R&D rationalization?
A8: Suggested hashtags
A9: #Pharma #Biotech #DrugDevelopment #Oncology #Strategy #MergersAndAcquisitions

Sheet Sources
A1: Source | B1: Date | C1: Use | D1: URL
A2: AstraZeneca Development Pipeline 2025 | B2: 2026-02-10 | C2: Matched portfolio count and program stage | D2: https://www.astrazeneca.com/content/dam/az/Investor_Relations/annual-report-2025/pdf/AstraZeneca_Development_Pipeline_2025.pdf
A3: BMS Development Portfolio 2025 | B3: 2026-02-05 | C3: Matched portfolio count and program stage | D3: https://annual-report.bms.com/assets/bms-ar/documents/2025/2025-bms-development-portfolio.pdf
A4: ClinicalTrials.gov | B4: Records checked through 2026-08-05 | C4: Trial phase, setting and primary-completion timing | D4: https://clinicaltrials.gov/
A5: AstraZeneca 2025 Form 20-F | B5: 2026-02-24 | C5: 2023-2025 product revenue and disclosed patent / exclusivity dates | D5: https://www.sec.gov/Archives/edgar/data/901832/000110465926019130/azn-20251231x20f.htm
A6: BMS Key Facts | B6: Updated May 2026 | C6: 2025 product revenue benchmarks | D6: https://www.bms.com/investors/financial-reporting/key-facts.html
A7: BMS FY2021 Results | B7: 2022-02-04 | C7: Historical multiple-myeloma franchise benchmark | D7: https://news.bms.com/news/details/2022/Bristol-Myers-Squibb-Reports-Fourth-Quarter-and-Full-Year-Financial-Results-for-2021/default.aspx
A8: AstraZeneca H1 and Q2 2026 results | B8: 2026-07-27 | C8: Etcamah and Baxfendy brand status; H1 2026 product revenue; Farxiga LOE impact | D8: https://www.rns-pdf.londonstockexchange.com/rns/9440N_1-2026-7-26.pdf
A9: BMS 2025 Form 10-K | B9: 2026-02-10 | C9: 2023-2025 product revenue and minimum market-exclusivity dates | D9: https://www.sec.gov/Archives/edgar/data/14272/000001427226000004/bmy-20251231.htm
A10: BMS Q2 2026 results | B10: 2026-07-30 | C10: H1 2026 product revenue used to derive 2026E run-rate scenarios | D10: https://www.bms.com/assets/bms/us/en-us/pdf/investor-info/doc_financials/quarterly_reports/2026/ghBMY-Q2-2026-Earnings-Press-Release.pdf

Sheet Infographic
A1: LinkedIn infographic - stacked footprint + count-based lollipop matrix
A2: Bars use logo-inspired company colors; bubbles use a red directness scale.

Sheet Fit_Collision_Matrix
A1: Fit vs collision matrix - indication territory × modality family
A2: AZ-only and BMS-only cells indicate complementarity in the matched late-stage snapshot; overlap cells indicate both companies occupy the same normalized modality × indication territory.
A4: Disease area | B4: Modality family | C4: Indication territory | D4: Status | E4: AZ count | F4: BMS count | G4: AZ programs | H4: BMS programs | I4: AZ source | J4: BMS source
A5: Solid-tumor oncology | B5: Antibody-drug conjugate | C5: NSCLC | D5: bms-only | E5: 0 | F5: 1 | H5: izalontamab brengitecan (iza-bren) | I5: https://www.astrazeneca.com/content/dam/az/Investor_Relations/annual-report-2025/pdf/AstraZeneca_Development_Pipeline_2025.pdf | J5: https://annual-report.bms.com/assets/bms-ar/documents/2025/2025-bms-development-portfolio.pdf
A6: Solid-tumor oncology | B6: Antibody-drug conjugate | C6: Breast cancer | D6: bms-only | E6: 0 | F6: 1 | H6: izalontamab brengitecan (iza-bren) | I6: https://www.astrazeneca.com/content/dam/az/Investor_Relations/annual-report-2025/pdf/AstraZeneca_Development_Pipeline_2025.pdf | J6: https://annual-report.bms.com/assets/bms-ar/documents/2025/2025-bms-development-portfolio.pdf
A7: Solid-tumor oncology | B7: Antibody-drug conjugate | C7: Gastric / GEJ | D7: az-only | E7: 1 | F7: 0 | G7: sonesitatug vedotin | I7: https://www.astrazeneca.com/content/dam/az/Investor_Relations/annual-report-2025/pdf/AstraZeneca_Development_Pipeline_2025.pdf | J7: https://annual-report.bms.com/assets/bms-ar/documents/2025/2025-bms-development-portfolio.pdf
A8: Solid-tumor oncology | B8: Antibody-drug conjugate | C8: Ovarian cancer | D8: az-only | E8: 1 | F8: 0 | G8: torvutatug samrotecan (AZD5335) | I8: https://www.astrazeneca.com/content/dam/az/Investor_Relations/annual-report-2025/pdf/AstraZeneca_Development_Pipeline_2025.pdf | J8: https://annual-report.bms.com/assets/bms-ar/documents/2025/2025-bms-development-portfolio.pdf
A9: Solid-tumor oncology | B9: Antibody-drug conjugate | C9: Endometrial cancer | D9: az-only | E9: 1 | F9: 0 | G9: puxitatug samrotecan | I9: https://www.astrazeneca.com/content/dam/az/Investor_Relations/annual-report-2025/pdf/AstraZeneca_Development_Pipeline_2025.pdf | J9: https://annual-report.bms.com/assets/bms-ar/documents/2025/2025-bms-development-portfolio.pdf
A10: Solid-tumor oncology | B10: Antibody-drug conjugate | C10: Urothelial cancer | D10: bms-only | E10: 0 | F10: 1 | H10: izalontamab brengitecan (iza-bren) | I10: https://www.astrazeneca.com/content/dam/az/Investor_Relations/annual-report-2025/pdf/AstraZeneca_Development_Pipeline_2025.pdf | J10: https://annual-report.bms.com/assets/bms-ar/documents/2025/2025-bms-development-portfolio.pdf
A11: Solid-tumor oncology | B11: Antibody-drug conjugate | C11: Other solid tumors | D11: az-only | E11: 4 | F11: 0 | G11: puxitatug samrotecan; sonesitatug vedotin; tilatamig samrotecan; torvutatug samrotecan (AZD5335) | I11: https://www.astrazeneca.com/content/dam/az/Investor_Relations/annual-report-2025/pdf/AstraZeneca_Development_Pipeline_2025.pdf | J11: https://annual-report.bms.com/assets/bms-ar/documents/2025/2025-bms-development-portfolio.pdf
A12: Solid-tumor oncology | B12: Bispecific / dual-target antibody | C12: NSCLC | D12: overlap | E12: 2 | F12: 1 | G12: rilvegostomig; volrustomig | H12: pumitamig | I12: https://www.astrazeneca.com/content/dam/az/Investor_Relations/annual-report-2025/pdf/AstraZeneca_Development_Pipeline_2025.pdf | J12: https://annual-report.bms.com/assets/bms-ar/documents/2025/2025-bms-development-portfolio.pdf
A13: Solid-tumor oncology | B13: Bispecific / dual-target antibody | C13: SCLC | D13: bms-only | E13: 0 | F13: 1 | H13: pumitamig | I13: https://www.astrazeneca.com/content/dam/az/Investor_Relations/annual-report-2025/pdf/AstraZeneca_Development_Pipeline_2025.pdf | J13: https://annual-report.bms.com/assets/bms-ar/documents/2025/2025-bms-development-portfolio.pdf
A14: Solid-tumor oncology | B14: Bispecific / dual-target antibody | C14: Breast cancer | D14: bms-only | E14: 0 | F14: 1 | H14: pumitamig | I14: https://www.astrazeneca.com/content/dam/az/Investor_Relations/annual-report-2025/pdf/AstraZeneca_Development_Pipeline_2025.pdf | J14: https://annual-report.bms.com/assets/bms-ar/documents/2025/2025-bms-development-portfolio.pdf
A15: Solid-tumor oncology | B15: Bispecific / dual-target antibody | C15: Gastric / GEJ | D15: az-only | E15: 1 | F15: 0 | G15: rilvegostomig | I15: https://www.astrazeneca.com/content/dam/az/Investor_Relations/annual-report-2025/pdf/AstraZeneca_Development_Pipeline_2025.pdf | J15: https://annual-report.bms.com/assets/bms-ar/documents/2025/2025-bms-development-portfolio.pdf
A16: Solid-tumor oncology | B16: Bispecific / dual-target antibody | C16: HCC / biliary | D16: az-only | E16: 1 | F16: 0 | G16: rilvegostomig | I16: https://www.astrazeneca.com/content/dam/az/Investor_Relations/annual-report-2025/pdf/AstraZeneca_Development_Pipeline_2025.pdf | J16: https://annual-report.bms.com/assets/bms-ar/documents/2025/2025-bms-development-portfolio.pdf
A17: Solid-tumor oncology | B17: Bispecific / dual-target antibody | C17: Other solid tumors | D17: overlap | E17: 2 | F17: 1 | G17: rilvegostomig; volrustomig | H17: pumitamig | I17: https://www.astrazeneca.com/content/dam/az/Investor_Relations/annual-report-2025/pdf/AstraZeneca_Development_Pipeline_2025.pdf | J17: https://annual-report.bms.com/assets/bms-ar/documents/2025/2025-bms-development-portfolio.pdf
A18: Solid-tumor oncology | B18: Small molecule / targeted degradation | C18: NSCLC | D18: bms-only | E18: 0 | F18: 1 | H18: navlimetostat | I18: https://www.astrazeneca.com/content/dam/az/Investor_Relations/annual-report-2025/pdf/AstraZeneca_Development_Pipeline_2025.pdf | J18: https://annual-report.bms.com/assets/bms-ar/documents/2025/2025-bms-development-portfolio.pdf
A19: Solid-tumor oncology | B19: Small molecule / targeted degradation | C19: Breast cancer | D19: az-only | E19: 2 | F19: 0 | G19: camizestrant; saruparib | I19: https://www.astrazeneca.com/content/dam/az/Investor_Relations/annual-report-2025/pdf/AstraZeneca_Development_Pipeline_2025.pdf | J19: https://annual-report.bms.com/assets/bms-ar/documents/2025/2025-bms-development-portfolio.pdf
A20: Solid-tumor oncology | B20: Small molecule / targeted degradation | C20: Prostate cancer | D20: overlap | E20: 1 | F20: 1 | G20: saruparib | H20: AR ligand-directed degrader | I20: https://www.astrazeneca.com/content/dam/az/Investor_Relations/annual-report-2025/pdf/AstraZeneca_Development_Pipeline_2025.pdf | J20: https://annual-report.bms.com/assets/bms-ar/documents/2025/2025-bms-development-portfolio.pdf
A21: Solid-tumor oncology | B21: Small molecule / targeted degradation | C21: Pancreatic cancer | D21: bms-only | E21: 0 | F21: 1 | H21: navlimetostat | I21: https://www.astrazeneca.com/content/dam/az/Investor_Relations/annual-report-2025/pdf/AstraZeneca_Development_Pipeline_2025.pdf | J21: https://annual-report.bms.com/assets/bms-ar/documents/2025/2025-bms-development-portfolio.pdf
A22: Solid-tumor oncology | B22: Small molecule / targeted degradation | C22: Other solid tumors | D22: overlap | E22: 1 | F22: 1 | G22: AZD9574 | H22: navlimetostat | I22: https://www.astrazeneca.com/content/dam/az/Investor_Relations/annual-report-2025/pdf/AstraZeneca_Development_Pipeline_2025.pdf | J22: https://annual-report.bms.com/assets/bms-ar/documents/2025/2025-bms-development-portfolio.pdf
A23: Solid-tumor oncology | B23: mAb / IO combination | C23: NSCLC | D23: overlap | E23: 1 | F23: 1 | G23: IPH5201 | H23: nivolumab + relatlimab HD | I23: https://www.astrazeneca.com/content/dam/az/Investor_Relations/annual-report-2025/pdf/AstraZeneca_Development_Pipeline_2025.pdf | J23: https://annual-report.bms.com/assets/bms-ar/documents/2025/2025-bms-development-portfolio.pdf
A24: Solid-tumor oncology | B24: mAb / IO combination | C24: SCLC | D24: bms-only | E24: 0 | F24: 1 | H24: atigotatug + nivolumab | I24: https://www.astrazeneca.com/content/dam/az/Investor_Relations/annual-report-2025/pdf/AstraZeneca_Development_Pipeline_2025.pdf | J24: https://annual-report.bms.com/assets/bms-ar/documents/2025/2025-bms-development-portfolio.pdf
A25: Solid-tumor oncology | B25: Radiopharmaceutical | C25: Prostate cancer | D25: az-only | E25: 1 | F25: 0 | G25: FPI-2265 | I25: https://www.astrazeneca.com/content/dam/az/Investor_Relations/annual-report-2025/pdf/AstraZeneca_Development_Pipeline_2025.pdf | J25: https://annual-report.bms.com/assets/bms-ar/documents/2025/2025-bms-development-portfolio.pdf
A26: Solid-tumor oncology | B26: Radiopharmaceutical | C26: GEP-NET | D26: bms-only | E26: 0 | F26: 1 | H26: RYZ101 | I26: https://www.astrazeneca.com/content/dam/az/Investor_Relations/annual-report-2025/pdf/AstraZeneca_Development_Pipeline_2025.pdf | J26: https://annual-report.bms.com/assets/bms-ar/documents/2025/2025-bms-development-portfolio.pdf
A27: Hematology | B27: CAR-T | C27: Multiple myeloma | D27: overlap | E27: 1 | F27: 1 | G27: AZD0120 | H27: arlo-cel | I27: https://www.astrazeneca.com/content/dam/az/Investor_Relations/annual-report-2025/pdf/AstraZeneca_Development_Pipeline_2025.pdf | J27: https://annual-report.bms.com/assets/bms-ar/documents/2025/2025-bms-development-portfolio.pdf
A28: Hematology | B28: Antibody-drug conjugate | C28: Multiple myeloma | D28: az-only | E28: 1 | F28: 0 | G28: AZD0305 | I28: https://www.astrazeneca.com/content/dam/az/Investor_Relations/annual-report-2025/pdf/AstraZeneca_Development_Pipeline_2025.pdf | J28: https://annual-report.bms.com/assets/bms-ar/documents/2025/2025-bms-development-portfolio.pdf
A29: Hematology | B29: T-cell engager | C29: B-cell lymphoma | D29: az-only | E29: 1 | F29: 0 | G29: surovatamig | I29: https://www.astrazeneca.com/content/dam/az/Investor_Relations/annual-report-2025/pdf/AstraZeneca_Development_Pipeline_2025.pdf | J29: https://annual-report.bms.com/assets/bms-ar/documents/2025/2025-bms-development-portfolio.pdf
A30: Hematology | B30: T-cell engager | C30: B-ALL | D30: az-only | E30: 1 | F30: 0 | G30: surovatamig | I30: https://www.astrazeneca.com/content/dam/az/Investor_Relations/annual-report-2025/pdf/AstraZeneca_Development_Pipeline_2025.pdf | J30: https://annual-report.bms.com/assets/bms-ar/documents/2025/2025-bms-development-portfolio.pdf
A31: Hematology | B31: Targeted protein degradation / CELMoD | C31: Multiple myeloma | D31: bms-only | E31: 0 | F31: 2 | H31: iberdomide; mezigdomide | I31: https://www.astrazeneca.com/content/dam/az/Investor_Relations/annual-report-2025/pdf/AstraZeneca_Development_Pipeline_2025.pdf | J31: https://annual-report.bms.com/assets/bms-ar/documents/2025/2025-bms-development-portfolio.pdf
A32: Hematology | B32: Targeted protein degradation / CELMoD | C32: B-cell lymphoma | D32: bms-only | E32: 0 | F32: 1 | H32: golcadomide | I32: https://www.astrazeneca.com/content/dam/az/Investor_Relations/annual-report-2025/pdf/AstraZeneca_Development_Pipeline_2025.pdf | J32: https://annual-report.bms.com/assets/bms-ar/documents/2025/2025-bms-development-portfolio.pdf
A33: Hematology | B33: Small molecule | C33: Hodgkin lymphoma | D33: az-only | E33: 1 | F33: 0 | G33: AZD3470 | I33: https://www.astrazeneca.com/content/dam/az/Investor_Relations/annual-report-2025/pdf/AstraZeneca_Development_Pipeline_2025.pdf | J33: https://annual-report.bms.com/assets/bms-ar/documents/2025/2025-bms-development-portfolio.pdf
A34: Immunology, respiratory & fibrosis | B34: Oral / systemic small molecule | C34: Asthma | D34: az-only | E34: 1 | F34: 0 | G34: atuliflapon | I34: https://www.astrazeneca.com/content/dam/az/Investor_Relations/annual-report-2025/pdf/AstraZeneca_Development_Pipeline_2025.pdf | J34: https://annual-report.bms.com/assets/bms-ar/documents/2025/2025-bms-development-portfolio.pdf
